<?xml version="1.0" ?>
<!-- =================================================================================== -->
<!-- |    This document was autogenerated by xacro from pedestal_pi_no_gripper.xacro   | -->
<!-- |    EDITING THIS FILE BY HAND IS NOT RECOMMENDED                                 | -->
<!-- =================================================================================== -->
<robot name="pedestal_pi_no_gripper" xmlns:xacro="http://ros.org/wiki/xacro">
  <material name="Green">
    <color rgba="0.0 0.8 0.0 1.0"/>
  </material>
  <material name="OffWhite">
    <color rgba="0.8 0.8 0.8 0.9"/>
  </material>
  <material name="White">
    <color rgba="1.0 1.0 1.0 1.0"/>
  </material>
  <material name="DarkGray">
    <color rgba="0.3 0.3 0.3 1.0"/>
  </material>
  <material name="LightGray">
    <color rgba="0.6 0.6 0.6 1.0"/>
  </material>
  <material name="Red">
    <color rgba="1.0 0.0 0.0 0.5"/>
  </material>
  <link name="base_link">
    <visual>
      <origin rpy="0 0 1.57" xyz="0 0 0.004"/>
      <geometry>
        <mesh filename="package://rbx2_description/meshes/pedestal_pi/pedestal_pi.dae" scale="1.0 1.0 1.0"/>
      </geometry>
    </visual>
    <!--
    <collision>
      <origin xyz="0 0 ${GROUND_CLEARANCE + LOWER_BASE_HEIGHT/2}" rpy="0 0 1.57" />
       <geometry>
          <cylinder length="${LOWER_BASE_HEIGHT}" radius="${LOWER_BASE_RADIUS}" />
       </geometry>
     </collision>
     -->
    <collision>
      <origin rpy="0 0 1.57" xyz="0 0 0.004"/>
      <geometry>
        <mesh filename="package://rbx2_description/meshes/pedestal_pi/pedestal_pi_collision.dae" scale="0.0254 0.0254 0.0254"/>
      </geometry>
    </collision>
  </link>
  <!-- Add a foot_print link and joint -->
  <link name="base_footprint">
    <visual>
      <origin rpy="0 0 0" xyz="0 0 0"/>
      <geometry>
        <box size="0.01 0.01 0.0001"/>
      </geometry>
    </visual>
  </link>
  <joint name="base_to_footprint" type="fixed">
    <origin rpy="0 0 0" xyz="0 0 0"/>
    <parent link="base_link"/>
    <child link="base_footprint"/>
  </joint>
  <!-- Attach the head -->
  <joint name="head_base_joint" type="fixed">
    <origin rpy="1.570795 0 1.570795" xyz="-0.01225 0 0.442"/>
    <parent link="base_link"/>
    <child link="head_base_link"/>
  </joint>
  <link name="head_base_link">
    <origin rpy="0 0 0" xyz="0 0 0"/>
    <inertial>
      <mass value="0.00001"/>
      <inertia ixx="1.0" ixy="0.0" ixz="0.0" iyy="1.0" iyz="0.0" izz="1.0"/>
    </inertial>
    <visual>
      <origin rpy="0 0 0" xyz="0 0 0 "/>
      <geometry>
        <cylinder length="0.00001" radius="0.01"/>
      </geometry>
    </visual>
    <collision>
      <origin rpy="0 0 0" xyz="0 0 0 "/>
      <geometry>
        <cylinder length="0.00001" radius="0.01"/>
      </geometry>
    </collision>
  </link>
  <joint name="head_pan_servo_joint" type="fixed">
    <origin rpy="0 3.14159 0" xyz="0 0 0"/>
    <parent link="head_base_link"/>
    <child link="head_pan_servo_link"/>
  </joint>
  <link name="head_pan_servo_link">
    <inertial>
      <mass value="0.00001"/>
      <origin xyz="0 0 0"/>
      <inertia ixx="1.0" ixy="0.0" ixz="0.0" iyy="1.0" iyz="0.0" izz="1.0"/>
    </inertial>
    <visual>
      <origin rpy="0 0 0" xyz=" 0 0 0 "/>
      <geometry>
        <mesh filename="package://rbx2_description/meshes/ax12.stl" scale="0.001 0.001 0.001"/>
      </geometry>
      <material name="Black"/>
    </visual>
    <collision>
      <origin rpy="0 0 0" xyz="0.0 0.0 -0.01241"/>
      <geometry>
        <box size="0.025 0.038 0.04762"/>
      </geometry>
    </collision>
  </link>
  <joint name="head_pan_joint" type="revolute">
    <origin rpy="-1.570795 1.570795 3.14159" xyz="0 0.0225 0"/>
    <parent link="head_pan_servo_link"/>
    <axis xyz="0 0 -1"/>
    <limit effort="1.0" lower="-2.9" upper="2.9" velocity="1.571"/>
    <child link="head_pan_bracket_link"/>
  </joint>
  <link name="head_pan_bracket_link">
    <inertial>
      <mass value="0.00001"/>
      <origin xyz="0 0 0"/>
      <inertia ixx="1.0" ixy="0.0" ixz="0.0" iyy="1.0" iyz="0.0" izz="1.0"/>
    </inertial>
    <visual>
      <origin rpy="0 0 0" xyz="0 0 0 "/>
      <geometry>
        <mesh filename="package://rbx2_description/meshes/F3.stl" scale="0.001 0.001 0.001"/>
      </geometry>
      <material name="White"/>
    </visual>
    <collision>
      <origin rpy="0 0 0" xyz="0 0 0"/>
      <geometry>
        <box size="0.025 0.038 0.009"/>
      </geometry>
    </collision>
  </link>
  <joint name="head_tilt_servo_joint" type="fixed">
    <origin rpy="0 3.14159 3.14159" xyz="0 0 -0.0415"/>
    <parent link="head_pan_bracket_link"/>
    <child link="head_tilt_servo_link"/>
  </joint>
  <link name="head_tilt_servo_link">
    <inertial>
      <mass value="0.00001"/>
      <origin xyz="0 0 0"/>
      <inertia ixx="1.0" ixy="0.0" ixz="0.0" iyy="1.0" iyz="0.0" izz="1.0"/>
    </inertial>
    <visual>
      <origin rpy="0 0 0" xyz=" 0 0 0 "/>
      <geometry>
        <mesh filename="package://rbx2_description/meshes/ax12.stl" scale="0.001 0.001 0.001"/>
      </geometry>
      <material name="Black"/>
    </visual>
    <collision>
      <origin rpy="0 0 0" xyz="0.0 0.0 -0.01241"/>
      <geometry>
        <box size="0.025 0.038 0.04762"/>
      </geometry>
    </collision>
  </link>
  <joint name="head_tilt_joint" type="revolute">
    <origin rpy="0 0 0" xyz="0 0 0"/>
    <parent link="head_tilt_servo_link"/>
    <axis xyz="0 1 0"/>
    <limit effort="1.0" lower="-2.9" upper="2.9" velocity="1.571"/>
    <child link="head_tilt_bracket_link"/>
  </joint>
  <link name="head_tilt_bracket_link">
    <inertial>
      <mass value="0.00001"/>
      <origin xyz="0 0 0"/>
      <inertia ixx="1.0" ixy="0.0" ixz="0.0" iyy="1.0" iyz="0.0" izz="1.0"/>
    </inertial>
    <visual>
      <origin rpy="0 0 0" xyz="0 0 0 "/>
      <geometry>
        <mesh filename="package://rbx2_description/meshes/F2.stl" scale="0.001 0.001 0.001"/>
      </geometry>
      <material name="White"/>
    </visual>
    <collision>
      <origin rpy="0 0 0" xyz="0 0 0"/>
      <geometry>
        <box size="0.0245 0.038 0.048"/>
      </geometry>
    </collision>
  </link>
  <joint name="head_tilt_bracket_camera_joint" type="fixed">
    <origin rpy="0 0 0" xyz="0.0 0.0 0.0615"/>
    <parent link="head_tilt_bracket_link"/>
    <child link="camera_link"/>
  </joint>
  <link name="camera_link">
    <visual>
      <origin rpy="0 0 1.570795" xyz="0 0 0"/>
      <geometry>
        <mesh filename="package://rbx2_description/meshes/kinect.dae" scale="1.0 1.0 1.0"/>
      </geometry>
      <material name="Black"/>
    </visual>
    <collision>
      <origin rpy="0 0 0" xyz="0 0 0"/>
      <geometry>
        <box size="0.07271 0.27794 0.07"/>
      </geometry>
    </collision>
  </link>
  <joint name="camera_depth_joint" type="fixed">
    <origin rpy="0 0 0" xyz="0 0.0125 0.015"/>
    <parent link="camera_link"/>
    <child link="camera_depth_frame"/>
  </joint>
  <link name="camera_depth_frame">
    <inertial>
      <mass value="0.000001"/>
      <origin xyz="0 0 0"/>
      <inertia ixx="0.0001" ixy="0.0" ixz="0.0" iyy="0.0001" iyz="0.0" izz="0.0001"/>
    </inertial>
  </link>
  <joint name="camera_depth_optical_joint" type="fixed">
    <origin rpy="-1.570795 0 -1.570795" xyz="0 0 0"/>
    <parent link="camera_depth_frame"/>
    <child link="camera_depth_optical_frame"/>
  </joint>
  <link name="camera_depth_optical_frame">
    <inertial>
      <mass value="0.000001"/>
      <origin xyz="0 0 0"/>
      <inertia ixx="0.0001" ixy="0.0" ixz="0.0" iyy="0.0001" iyz="0.0" izz="0.0001"/>
    </inertial>
  </link>
  <joint name="camera_rgb_joint" type="fixed">
    <origin rpy="0 0 0" xyz="0 -0.0125 0.015"/>
    <parent link="camera_link"/>
    <child link="camera_rgb_frame"/>
  </joint>
  <link name="camera_rgb_frame">
    <inertial>
      <mass value="0.000001"/>
      <origin xyz="0 0 0"/>
      <inertia ixx="0.0001" ixy="0.0" ixz="0.0" iyy="0.0001" iyz="0.0" izz="0.0001"/>
    </inertial>
  </link>
  <joint name="camera_rgb_optical_joint" type="fixed">
    <origin rpy="-1.570795 0 -1.570795" xyz="0 0 0"/>
    <parent link="camera_rgb_frame"/>
    <child link="camera_rgb_optical_frame"/>
  </joint>
  <link name="camera_rgb_optical_frame">
    <inertial>
      <mass value="0.000001"/>
      <origin xyz="0 0 0"/>
      <inertia ixx="0.0001" ixy="0.0" ixz="0.0" iyy="0.0001" iyz="0.0" izz="0.0001"/>
    </inertial>
  </link>
  <!-- Attach the right arm -->
  <link name="right_arm_base_link"/>
  <joint name="right_arm_base_joint" type="fixed">
    <origin rpy="0 0 1.57" xyz="0 -0.068 0.38"/>
    <parent link="base_link"/>
    <child link="right_arm_base_link"/>
  </joint>
  <joint name="right_arm_shoulder_F2_0_joint" type="fixed">
    <origin rpy="1.570795 0 1.570795" xyz="0 0 0"/>
    <parent link="right_arm_base_link"/>
    <child link="right_arm_shoulder_F2_0_link"/>
  </joint>
  <link name="right_arm_shoulder_F2_0_link">
    <inertial>
      <mass value="0.00001"/>
      <origin xyz="0 0 0"/>
      <inertia ixx="1.0" ixy="0.0" ixz="0.0" iyy="1.0" iyz="0.0" izz="1.0"/>
    </inertial>
    <visual>
      <origin rpy="0 0 0" xyz=" 0 0 0 "/>
      <geometry>
        <mesh filename="package://rbx2_description/meshes/F2.stl" scale="0.001 0.001 0.001"/>
      </geometry>
      <material name="White"/>
    </visual>
    <collision>
      <origin rpy="0 0 0" xyz="0.0 0.0 0.00775"/>
      <geometry>
        <box size="0.025 0.0485 0.0375"/>
      </geometry>
    </collision>
  </link>
  <joint name="right_arm_shoulder_pan_joint" type="revolute">
    <origin rpy="0 0 0" xyz="0 0 0"/>
    <axis xyz="0 1 0"/>
    <limit effort="1.0" lower="-2.7" upper="1.8" velocity="1.571"/>
    <parent link="right_arm_shoulder_F2_0_link"/>
    <child link="right_arm_shoulder_pan_link"/>
  </joint>
  <link name="right_arm_shoulder_pan_link">
    <inertial>
      <mass value="0.00001"/>
      <origin xyz="0 0 0"/>
      <inertia ixx="1.0" ixy="0.0" ixz="0.0" iyy="1.0" iyz="0.0" izz="1.0"/>
    </inertial>
    <visual>
      <origin rpy="0 0 0" xyz=" 0 0 0 "/>
      <geometry>
        <mesh filename="package://rbx2_description/meshes/ax12.stl" scale="0.001 0.001 0.001"/>
      </geometry>
      <material name="Black"/>
    </visual>
    <collision>
      <origin rpy="0 0 0" xyz="0.0 0.0 -0.01241"/>
      <geometry>
        <box size="0.025 0.038 0.04762"/>
      </geometry>
    </collision>
  </link>
  <joint name="right_arm_shoulder_F3_0_joint" type="fixed">
    <origin rpy="0 3.14159 0" xyz="0 0 -0.0405"/>
    <parent link="right_arm_shoulder_pan_link"/>
    <child link="right_arm_shoulder_F3_0_link"/>
  </joint>
  <link name="right_arm_shoulder_F3_0_link">
    <inertial>
      <mass value="0.00001"/>
      <origin xyz="0 0 0"/>
      <inertia ixx="1.0" ixy="0.0" ixz="0.0" iyy="1.0" iyz="0.0" izz="1.0"/>
    </inertial>
    <visual>
      <origin rpy="0 0 0" xyz=" 0 0 0 "/>
      <geometry>
        <mesh filename="package://rbx2_description/meshes/F3.stl" scale="0.001 0.001 0.001"/>
      </geometry>
      <material name="White"/>
    </visual>
    <collision>
      <origin rpy="0 0 0" xyz="0.0 0.0 -0.0045"/>
      <geometry>
        <box size="0.025 0.038 0.009"/>
      </geometry>
    </collision>
  </link>
  <joint name="right_arm_shoulder_lift_joint" type="revolute">
    <origin rpy="1.570795 3.14159 3.14159" xyz="0 0.002 0.0175"/>
    <axis xyz="0 -1 0"/>
    <limit effort="1.0" lower="-1.75" upper="4.19" velocity="1.571"/>
    <parent link="right_arm_shoulder_F3_0_link"/>
    <child link="right_arm_shoulder_lift_link"/>
  </joint>
  <link name="right_arm_shoulder_lift_link">
    <inertial>
      <mass value="0.00001"/>
      <origin xyz="0 0 0"/>
      <inertia ixx="1.0" ixy="0.0" ixz="0.0" iyy="1.0" iyz="0.0" izz="1.0"/>
    </inertial>
    <visual>
      <origin rpy="0 0 0" xyz=" 0 0 0 "/>
      <geometry>
        <mesh filename="package://rbx2_description/meshes/ax12.stl" scale="0.001 0.001 0.001"/>
      </geometry>
      <material name="Black"/>
    </visual>
    <collision>
      <origin rpy="0 0 0" xyz="0.0 0.0 -0.01241"/>
      <geometry>
        <box size="0.025 0.038 0.04762"/>
      </geometry>
    </collision>
  </link>
  <joint name="right_arm_shoulder_F3_1_joint" type="fixed">
    <origin rpy="3.14159 0 0" xyz="0 0 -0.0405"/>
    <parent link="right_arm_shoulder_lift_link"/>
    <child link="right_arm_shoulder_F3_1_link"/>
  </joint>
  <link name="right_arm_shoulder_F3_1_link">
    <inertial>
      <mass value="0.00001"/>
      <origin xyz="0 0 0"/>
      <inertia ixx="1.0" ixy="0.0" ixz="0.0" iyy="1.0" iyz="0.0" izz="1.0"/>
    </inertial>
    <visual>
      <origin rpy="0 0 0" xyz=" 0 0 0 "/>
      <geometry>
        <mesh filename="package://rbx2_description/meshes/F3.stl" scale="0.001 0.001 0.001"/>
      </geometry>
      <material name="White"/>
    </visual>
    <collision>
      <origin rpy="0 0 0" xyz="0.0 0.0 -0.0045"/>
      <geometry>
        <box size="0.025 0.038 0.009"/>
      </geometry>
    </collision>
  </link>
  <joint name="right_arm_shoulder_roll_joint" type="revolute">
    <origin rpy="-1.570795 0 -1.570795" xyz="0 0 0.01925"/>
    <axis xyz="0 1 0"/>
    <limit effort="1.0" lower="-2.617" upper="2.617" velocity="1.571"/>
    <parent link="right_arm_shoulder_F3_1_link"/>
    <child link="right_arm_shoulder_roll_link"/>
  </joint>
  <link name="right_arm_shoulder_roll_link">
    <inertial>
      <mass value="0.00001"/>
      <origin xyz="0 0 0"/>
      <inertia ixx="1.0" ixy="0.0" ixz="0.0" iyy="1.0" iyz="0.0" izz="1.0"/>
    </inertial>
    <visual>
      <origin rpy="0 0 0" xyz=" 0 0 0 "/>
      <geometry>
        <mesh filename="package://rbx2_description/meshes/ax12.stl" scale="0.001 0.001 0.001"/>
      </geometry>
      <material name="Black"/>
    </visual>
    <collision>
      <origin rpy="0 0 0" xyz="0.0 0.0 -0.01241"/>
      <geometry>
        <box size="0.025 0.038 0.04762"/>
      </geometry>
    </collision>
  </link>
  <joint name="right_arm_shoulder_roll_F3_0_joint" type="fixed">
    <origin rpy="0 1.570795 0" xyz="0.0175 0 -0.0055"/>
    <parent link="right_arm_shoulder_roll_link"/>
    <child link="right_arm_shoulder_roll_F3_0_link"/>
  </joint>
  <link name="right_arm_shoulder_roll_F3_0_link">
    <inertial>
      <mass value="0.00001"/>
      <origin xyz="0 0 0"/>
      <inertia ixx="1.0" ixy="0.0" ixz="0.0" iyy="1.0" iyz="0.0" izz="1.0"/>
    </inertial>
    <visual>
      <origin rpy="0 0 0" xyz=" 0 0 0 "/>
      <geometry>
        <mesh filename="package://rbx2_description/meshes/F3.stl" scale="0.001 0.001 0.001"/>
      </geometry>
      <material name="White"/>
    </visual>
    <collision>
      <origin rpy="0 0 0" xyz="0.0 0.0 -0.0045"/>
      <geometry>
        <box size="0.025 0.038 0.009"/>
      </geometry>
    </collision>
  </link>
  <joint name="right_arm_shoulder_roll_F9_0_joint" type="fixed">
    <origin rpy="0 1.570795 0" xyz="0 -0.0125 -0.0085"/>
    <parent link="right_arm_shoulder_roll_F3_0_link"/>
    <child link="right_arm_shoulder_roll_F9_0_link"/>
  </joint>
  <link name="right_arm_shoulder_roll_F9_0_link">
    <inertial>
      <mass value="0.00001"/>
      <origin xyz="0 0 0"/>
      <inertia ixx="1.0" ixy="0.0" ixz="0.0" iyy="1.0" iyz="0.0" izz="1.0"/>
    </inertial>
    <visual>
      <origin rpy="0 0 0" xyz=" 0 0 0 "/>
      <geometry>
        <mesh filename="package://rbx2_description/meshes/F9.stl" scale="0.001 0.001 0.001"/>
      </geometry>
      <material name="White"/>
    </visual>
    <collision>
      <origin rpy="0 0 0" xyz="0.0 0.0 -0.0045"/>
      <geometry>
        <box size="0.025 0.030 0.025"/>
      </geometry>
    </collision>
  </link>
  <joint name="right_arm_elbow_F3_0_joint" type="fixed">
    <origin rpy="1.570795 3.14159 3.14159" xyz="0 -0.01575 0"/>
    <parent link="right_arm_shoulder_roll_F9_0_link"/>
    <child link="right_arm_elbow_F3_0_link"/>
  </joint>
  <link name="right_arm_elbow_F3_0_link">
    <inertial>
      <mass value="0.00001"/>
      <origin xyz="0 0 0"/>
      <inertia ixx="1.0" ixy="0.0" ixz="0.0" iyy="1.0" iyz="0.0" izz="1.0"/>
    </inertial>
    <visual>
      <origin rpy="0 0 0" xyz=" 0 0 0 "/>
      <geometry>
        <mesh filename="package://rbx2_description/meshes/F3.stl" scale="0.001 0.001 0.001"/>
      </geometry>
      <material name="White"/>
    </visual>
    <collision>
      <origin rpy="0 0 0" xyz="0.0 0.0 -0.0045"/>
      <geometry>
        <box size="0.025 0.038 0.009"/>
      </geometry>
    </collision>
  </link>
  <joint name="right_arm_elbow_flex_servo_joint" type="fixed">
    <origin rpy="0 3.14159 0" xyz="0 0 -0.0395"/>
    <parent link="right_arm_elbow_F3_0_link"/>
    <child link="right_arm_elbow_flex_servo_link"/>
  </joint>
  <link name="right_arm_elbow_flex_servo_link">
    <inertial>
      <mass value="0.00001"/>
      <origin xyz="0 0 0"/>
      <inertia ixx="1.0" ixy="0.0" ixz="0.0" iyy="1.0" iyz="0.0" izz="1.0"/>
    </inertial>
    <visual>
      <origin rpy="0 0 0" xyz=" 0 0 0 "/>
      <geometry>
        <mesh filename="package://rbx2_description/meshes/ax12.stl" scale="0.001 0.001 0.001"/>
      </geometry>
      <material name="Black"/>
    </visual>
    <collision>
      <origin rpy="0 0 0" xyz="0.0 0.0 -0.01241"/>
      <geometry>
        <box size="0.025 0.038 0.04762"/>
      </geometry>
    </collision>
  </link>
  <joint name="right_arm_elbow_flex_joint" type="revolute">
    <origin rpy="0 0 0" xyz="0 0 0"/>
    <axis xyz="0 1 0"/>
    <limit effort="1.0" lower="-1.8" upper="1.8" velocity="1.571"/>
    <parent link="right_arm_elbow_flex_servo_link"/>
    <child link="right_arm_elbow_flex_link"/>
  </joint>
  <link name="right_arm_elbow_flex_link">
    <inertial>
      <mass value="0.00001"/>
      <origin xyz="0 0 0"/>
      <inertia ixx="1.0" ixy="0.0" ixz="0.0" iyy="1.0" iyz="0.0" izz="1.0"/>
    </inertial>
    <visual>
      <origin rpy="0 0 0" xyz=" 0 0 0 "/>
      <geometry>
        <mesh filename="package://rbx2_description/meshes/F2.stl" scale="0.001 0.001 0.001"/>
      </geometry>
      <material name="White"/>
    </visual>
    <collision>
      <origin rpy="0 0 0" xyz="0.0 0.0 0.00775"/>
      <geometry>
        <box size="0.025 0.0485 0.0375"/>
      </geometry>
    </collision>
  </link>
  <joint name="right_arm_forearm_F3_0_joint" type="fixed">
    <origin rpy="3.14159 0 1.570795" xyz="0 0 0.02675"/>
    <parent link="right_arm_elbow_flex_link"/>
    <child link="right_arm_forearm_F3_0_link"/>
  </joint>
  <link name="right_arm_forearm_F3_0_link">
    <inertial>
      <mass value="0.00001"/>
      <origin xyz="0 0 0"/>
      <inertia ixx="1.0" ixy="0.0" ixz="0.0" iyy="1.0" iyz="0.0" izz="1.0"/>
    </inertial>
    <visual>
      <origin rpy="0 0 0" xyz=" 0 0 0 "/>
      <geometry>
        <mesh filename="package://rbx2_description/meshes/F3.stl" scale="0.001 0.001 0.001"/>
      </geometry>
      <material name="White"/>
    </visual>
    <collision>
      <origin rpy="0 0 0" xyz="0.0 0.0 -0.0045"/>
      <geometry>
        <box size="0.025 0.038 0.009"/>
      </geometry>
    </collision>
  </link>
  <joint name="right_arm_forearm_flex_servo_joint" type="fixed">
    <origin rpy="3.14159 0 0" xyz="0 0 -0.04375"/>
    <parent link="right_arm_forearm_F3_0_link"/>
    <child link="right_arm_forearm_flex_servo_link"/>
  </joint>
  <link name="right_arm_forearm_flex_servo_link">
    <inertial>
      <mass value="0.00001"/>
      <origin xyz="0 0 0"/>
      <inertia ixx="1.0" ixy="0.0" ixz="0.0" iyy="1.0" iyz="0.0" izz="1.0"/>
    </inertial>
    <visual>
      <origin rpy="0 0 0" xyz=" 0 0 0 "/>
      <geometry>
        <mesh filename="package://rbx2_description/meshes/ax12.stl" scale="0.001 0.001 0.001"/>
      </geometry>
      <material name="Black"/>
    </visual>
    <collision>
      <origin rpy="0 0 0" xyz="0.0 0.0 -0.01241"/>
      <geometry>
        <box size="0.025 0.038 0.04762"/>
      </geometry>
    </collision>
  </link>
  <joint name="right_arm_forearm_flex_joint" type="revolute">
    <origin rpy="0 0 0" xyz="0 0 0"/>
    <axis xyz="0 1 0"/>
    <limit effort="1.0" lower="-1.8" upper="1.8" velocity="1.571"/>
    <parent link="right_arm_forearm_flex_servo_link"/>
    <child link="right_arm_forearm_flex_link"/>
  </joint>
  <link name="right_arm_forearm_flex_link">
    <inertial>
      <mass value="0.00001"/>
      <origin xyz="0 0 0"/>
      <inertia ixx="1.0" ixy="0.0" ixz="0.0" iyy="1.0" iyz="0.0" izz="1.0"/>
    </inertial>
    <visual>
      <origin rpy="0 0 0" xyz=" 0 0 0 "/>
      <geometry>
        <mesh filename="package://rbx2_description/meshes/F2.stl" scale="0.001 0.001 0.001"/>
      </geometry>
      <material name="White"/>
    </visual>
    <collision>
      <origin rpy="0 0 0" xyz="0.0 0.0 0.00775"/>
      <geometry>
        <box size="0.025 0.0485 0.0375"/>
      </geometry>
    </collision>
  </link>
  <joint name="right_arm_forearm_F2_0_joint" type="fixed">
    <origin rpy="0 3.14159 1.570795" xyz="0 0 0.05325"/>
    <parent link="right_arm_forearm_flex_link"/>
    <child link="right_arm_forearm_F2_0_link"/>
  </joint>
  <link name="right_arm_forearm_F2_0_link">
    <inertial>
      <mass value="0.00001"/>
      <origin xyz="0 0 0"/>
      <inertia ixx="1.0" ixy="0.0" ixz="0.0" iyy="1.0" iyz="0.0" izz="1.0"/>
    </inertial>
    <visual>
      <origin rpy="0 0 0" xyz=" 0 0 0 "/>
      <geometry>
        <mesh filename="package://rbx2_description/meshes/F2.stl" scale="0.001 0.001 0.001"/>
      </geometry>
      <material name="White"/>
    </visual>
    <collision>
      <origin rpy="0 0 0" xyz="0.0 0.0 0.00775"/>
      <geometry>
        <box size="0.025 0.0485 0.0375"/>
      </geometry>
    </collision>
  </link>
  <joint name="right_arm_wrist_flex_joint" type="revolute">
    <origin rpy="0 0 0" xyz="0 0 0"/>
    <axis xyz="0 1 0"/>
    <limit effort="1.0" lower="-1.57" upper="1.57" velocity="1.571"/>
    <parent link="right_arm_forearm_F2_0_link"/>
    <child link="right_arm_wrist_flex_link"/>
  </joint>
  <link name="right_arm_wrist_flex_link">
    <inertial>
      <mass value="0.00001"/>
      <origin xyz="0 0 0"/>
      <inertia ixx="1.0" ixy="0.0" ixz="0.0" iyy="1.0" iyz="0.0" izz="1.0"/>
    </inertial>
    <visual>
      <origin rpy="0 0 0" xyz=" 0 0 0 "/>
      <geometry>
        <mesh filename="package://rbx2_description/meshes/ax12.stl" scale="0.001 0.001 0.001"/>
      </geometry>
      <material name="Black"/>
    </visual>
    <collision>
      <origin rpy="0 0 0" xyz="0.0 0.0 -0.01241"/>
      <geometry>
        <box size="0.025 0.038 0.04762"/>
      </geometry>
    </collision>
  </link>
  <joint name="right_hand_attach_joint" type="fixed">
    <origin rpy="3.14159 0 0" xyz="0 0 -0.043"/>
    <parent link="right_arm_wrist_flex_link"/>
    <child link="right_hand_attach_link"/>
  </joint>
  <link name="right_hand_attach_link">
    <inertial>
      <mass value="0.00001"/>
      <origin xyz="0 0 0"/>
      <inertia ixx="1.0" ixy="0.0" ixz="0.0" iyy="1.0" iyz="0.0" izz="1.0"/>
    </inertial>
    <visual>
      <origin rpy="0 0 0" xyz=" 0 0 0 "/>
      <geometry>
        <mesh filename="package://rbx2_description/meshes/F3.stl" scale="0.001 0.001 0.001"/>
      </geometry>
      <material name="White"/>
    </visual>
    <collision>
      <origin rpy="0 0 0" xyz="0.0 0.0 -0.0045"/>
      <geometry>
        <box size="0.025 0.038 0.009"/>
      </geometry>
    </collision>
  </link>
  <joint name="right_hand_joint" type="fixed">
    <origin rpy="1.570795 0 0" xyz="0 0 0.0021"/>
    <parent link="right_hand_attach_link"/>
    <child link="right_hand_link"/>
  </joint>
  <link name="right_hand_link">
    <inertial>
      <mass value="0.00001"/>
      <origin xyz="0 0 0"/>
      <inertia ixx="1.0" ixy="0.0" ixz="0.0" iyy="1.0" iyz="0.0" izz="1.0"/>
    </inertial>
    <visual>
      <origin rpy="0 0 0" xyz="0 0 0"/>
      <geometry>
        <mesh filename="package://rbx2_description/meshes/F11.stl" scale="0.001 0.001 0.001"/>
      </geometry>
      <material name="Grey">
        <color rgba="0.6 0.6 0.6 1.0"/>
      </material>
    </visual>
    <collision>
      <origin rpy="0 0 0" xyz="0 0.028 0"/>
      <geometry>
        <box size="0.030 0.056 0.032"/>
      </geometry>
    </collision>
  </link>
  <joint name="right_hand_planning_joint" type="fixed">
    <axis xyz="0 0 1"/>
    <origin rpy="3.14159 0 1.570795" xyz="0 0.02 0"/>
    <parent link="right_hand_link"/>
    <child link="right_hand_planning_link"/>
  </joint>
  <link name="right_hand_planning_link">
    <visual>
      <origin rpy="0 0 0" xyz="0 0 0"/>
      <geometry>
        <box size="0.001 0.0005 0.0005"/>
      </geometry>
    </visual>
  </link>
</robot>

