<?xml version="1.0" ?>
<!-- =================================================================================== -->
<!-- |    This document was autogenerated by xacro from box_robot_with_arm.xacro       | -->
<!-- |    EDITING THIS FILE BY HAND IS NOT RECOMMENDED                                 | -->
<!-- =================================================================================== -->
<robot name="box_robot" xmlns:xacro="http://ros.org/wiki/xacro">
  <!-- Define a number of dimensions using properties -->
  <!-- Include all component files -->
  <material name="Black">
    <color rgba="0.2 0.2 0.2 1.0"/>
  </material>
  <material name="TransparentBlack">
    <color rgba="0.2 0.2 0.2 0.8"/>
  </material>
  <material name="Orange">
    <color rgba="1.0  0.55 0.0 1.0"/>
  </material>
  <material name="Grey">
    <color rgba="0.7 0.7 0.7 1.0"/>
  </material>
  <material name="DarkGrey">
    <color rgba="0.3 0.3 0.3 1.0"/>
  </material>
  <material name="Red">
    <color rgba="0.8 0.0 0.0 1.0"/>
  </material>
  <material name="White">
    <color rgba="1.0 1.0 1.0 1.0"/>
  </material>
  <material name="OffWhite">
    <color rgba="0.8 0.8 0.8 1.0"/>
  </material>
  <material name="Blue">
    <color rgba="0.0 0.0 0.8 1.0"/>
  </material>
  <material name="Green">
    <color rgba="0.0 0.8 0.0 1.0"/>
  </material>
  <material name="TransparentGreen">
    <color rgba="0.0 0.8 0.0 0.5"/>
  </material>
  <link name="base_footprint">
    <visual>
      <origin rpy="0 0 0" xyz="0 0 0"/>
      <geometry>
        <box size="0.05 0.05 0.001"/>
      </geometry>
      <material name="TransparentGreen"/>
    </visual>
  </link>
  <joint name="base_joint" type="fixed">
    <origin rpy="0 0 0" xyz="0 0 0.098"/>
    <parent link="base_footprint"/>
    <child link="base_link"/>
  </joint>
  <joint name="base_l_wheel_joint" type="continuous">
    <axis xyz="0 0 1"/>
    <limit effort="100" velocity="100"/>
    <safety_controller k_velocity="10"/>
    <origin rpy="1.570795 0 0" xyz="0.09 0.17 -0.038"/>
    <parent link="base_link"/>
    <child link="base_l_wheel_link"/>
  </joint>
  <link name="base_l_wheel_link">
    <visual>
      <origin rpy="0 0 0" xyz="0 0 0"/>
      <geometry>
        <cylinder length="0.02032" radius="0.06191"/>
      </geometry>
      <material name="Orange"/>
    </visual>
  </link>
  <joint name="base_r_wheel_joint" type="continuous">
    <axis xyz="0 0 1"/>
    <limit effort="100" velocity="100"/>
    <safety_controller k_velocity="10"/>
    <origin rpy="-1.570795 0 0" xyz="0.09 -0.17 -0.038"/>
    <parent link="base_link"/>
    <child link="base_r_wheel_link"/>
  </joint>
  <link name="base_r_wheel_link">
    <visual>
      <origin rpy="0 0 0" xyz="0 0 0"/>
      <geometry>
        <cylinder length="0.02032" radius="0.06191"/>
      </geometry>
      <material name="Orange"/>
    </visual>
  </link>
  <!-- Add the base and wheels -->
  <link name="base_link">
    <visual>
      <origin rpy="0 0 0" xyz="0 0 0"/>
      <geometry>
        <box size="0.3 0.3 0.12"/>
      </geometry>
      <material name="Black"/>
    </visual>
    <collision>
      <origin rpy="0 0 0" xyz="0 0 0"/>
      <geometry>
        <box size="0.3 0.36032 0.12"/>
      </geometry>
    </collision>
  </link>
  <!-- Attach the torso -->
  <joint name="base_torso_joint" type="fixed">
    <origin rpy="0 0 0" xyz="-0.13 0.0 0.41"/>
    <parent link="base_link"/>
    <child link="torso_link"/>
  </joint>
  <link name="torso_link">
    <visual>
      <origin rpy="0 0 0" xyz="0 0 0"/>
      <geometry>
        <box size="0.0254 0.0254 0.7"/>
      </geometry>
      <material name="Grey"/>
    </visual>
    <collision>
      <origin rpy="0 0 0" xyz="0 0 0"/>
      <geometry>
        <box size="0.0254 0.0254 0.7"/>
      </geometry>
    </collision>
  </link>
  <!-- Attach the pan and tilt head -->
  <joint name="head_base_joint" type="fixed">
    <origin rpy="0 0 3.14159" xyz="0.0275 0.0 0.345"/>
    <parent link="torso_link"/>
    <child link="head_base_link"/>
  </joint>
  <link name="head_base_link">
    <origin rpy="0 0 0" xyz="0 0 0"/>
    <inertial>
      <mass value="0.00001"/>
      <inertia ixx="1.0" ixy="0.0" ixz="0.0" iyy="1.0" iyz="0.0" izz="1.0"/>
    </inertial>
    <visual>
      <origin rpy="0 0 0" xyz="0 0 0 "/>
      <geometry>
        <cylinder length="0.00001" radius="0.01"/>
      </geometry>
    </visual>
    <collision>
      <origin rpy="0 0 0" xyz="0 0 0 "/>
      <geometry>
        <cylinder length="0.00001" radius="0.01"/>
      </geometry>
    </collision>
  </link>
  <joint name="head_pan_servo_joint" type="fixed">
    <origin rpy="1.570795 0 -1.570795" xyz="-0.012 0 -0.0175"/>
    <parent link="head_base_link"/>
    <child link="head_pan_servo_link"/>
  </joint>
  <link name="head_pan_servo_link">
    <inertial>
      <mass value="0.00001"/>
      <origin xyz="0 0 0"/>
      <inertia ixx="1.0" ixy="0.0" ixz="0.0" iyy="1.0" iyz="0.0" izz="1.0"/>
    </inertial>
    <visual>
      <origin rpy="0 0 0" xyz="0 0 0"/>
      <geometry>
        <box size="0.0385 0.035 0.049"/>
      </geometry>
      <material name="Black"/>
    </visual>
    <collision>
      <origin rpy="0 0 0" xyz="0 0 -0.01241"/>
      <geometry>
        <box size="0.0385 0.035 0.049"/>
      </geometry>
    </collision>
  </link>
  <joint name="head_pan_joint" type="revolute">
    <origin rpy="-1.570795 1.570795 3.14159" xyz="0 0.0225 0.012"/>
    <axis xyz="0 0 -1"/>
    <parent link="head_pan_servo_link"/>
    <limit effort="1.0" lower="-2.9" upper="2.9" velocity="1.571"/>
    <child link="head_pan_bracket_link"/>
  </joint>
  <link name="head_pan_bracket_link">
    <inertial>
      <mass value="0.00001"/>
      <origin xyz="0 0 0"/>
      <inertia ixx="1.0" ixy="0.0" ixz="0.0" iyy="1.0" iyz="0.0" izz="1.0"/>
    </inertial>
    <visual>
      <origin rpy="0 0 0" xyz="0 0 0 "/>
      <geometry>
        <box size="0.025 0.038 0.009"/>
      </geometry>
      <material name="White"/>
    </visual>
    <collision>
      <origin rpy="0 0 0" xyz="0 0 0"/>
      <geometry>
        <box size="0.025 0.038 0.009"/>
      </geometry>
    </collision>
  </link>
  <joint name="head_tilt_servo_joint" type="fixed">
    <origin rpy="0 3.14159 0" xyz="0 0 -0.031"/>
    <parent link="head_pan_bracket_link"/>
    <child link="head_tilt_servo_link"/>
  </joint>
  <link name="head_tilt_servo_link">
    <inertial>
      <mass value="0.00001"/>
      <origin xyz="0 0 0"/>
      <inertia ixx="1.0" ixy="0.0" ixz="0.0" iyy="1.0" iyz="0.0" izz="1.0"/>
    </inertial>
    <visual>
      <origin rpy="0 0 0" xyz="0 0 0"/>
      <geometry>
        <box size="0.0385 0.035 0.049"/>
      </geometry>
      <material name="Black"/>
    </visual>
    <collision>
      <origin rpy="0 0 0" xyz="0 0 -0.01241"/>
      <geometry>
        <box size="0.0385 0.035 0.049"/>
      </geometry>
    </collision>
  </link>
  <joint name="head_tilt_joint" type="revolute">
    <origin rpy="0 0 0" xyz="0 0 0.025"/>
    <parent link="head_tilt_servo_link"/>
    <axis xyz="0 1 0"/>
    <limit effort="1.0" lower="-2.9" upper="2.9" velocity="1.571"/>
    <child link="head_tilt_bracket_link"/>
  </joint>
  <link name="head_tilt_bracket_link">
    <inertial>
      <mass value="0.00001"/>
      <origin xyz="0 0 0"/>
      <inertia ixx="1.0" ixy="0.0" ixz="0.0" iyy="1.0" iyz="0.0" izz="1.0"/>
    </inertial>
    <visual>
      <origin rpy="0 0 0" xyz="0 0 0 "/>
      <geometry>
        <box size="0.0245 0.048 0.038"/>
      </geometry>
      <material name="White"/>
    </visual>
    <collision>
      <origin rpy="0 0 0" xyz="0 0 0"/>
      <geometry>
        <box size="0.0245 0.048 0.038"/>
      </geometry>
    </collision>
  </link>
  <link name="left_eye_link">
    <visual>
      <origin rpy="0 1.57 0" xyz="0 0 0"/>
      <geometry>
        <cylinder length="0.01" radius="0.01"/>
      </geometry>
      <material name="OffWhite"/>
    </visual>
    <collision>
      <origin rpy="0 1.57 0" xyz="0 0 0"/>
      <geometry>
        <cylinder length="0.01" radius="0.01"/>
      </geometry>
    </collision>
    <inertial>
      <mass value="0.00001"/>
      <origin xyz="0 0 0"/>
      <inertia ixx="1.0" ixy="0.0" ixz="0.0" iyy="1.0" iyz="0.0" izz="1.0"/>
    </inertial>
  </link>
  <link name="right_eye_link">
    <visual>
      <origin rpy="0 1.57 0" xyz="0 0 0"/>
      <geometry>
        <cylinder length="0.01" radius="0.01"/>
      </geometry>
      <material name="OffWhite"/>
    </visual>
    <collision>
      <origin rpy="0 1.57 0" xyz="0 0 0"/>
      <geometry>
        <cylinder length="0.01" radius="0.01"/>
      </geometry>
    </collision>
    <inertial>
      <mass value="0.00001"/>
      <origin xyz="0 0 0"/>
      <inertia ixx="1.0" ixy="0.0" ixz="0.0" iyy="1.0" iyz="0.0" izz="1.0"/>
    </inertial>
  </link>
  <joint name="left_eye_joint" type="fixed">
    <parent link="camera_link"/>
    <child link="left_eye_link"/>
    <origin rpy="0 0 0" xyz="0.034355 0.035 0"/>
  </joint>
  <joint name="right_eye_joint" type="fixed">
    <parent link="camera_link"/>
    <child link="right_eye_link"/>
    <origin rpy="0 0 0" xyz="0.034355 -0.035 0"/>
  </joint>
  <joint name="head_tilt_bracket_camera_joint" type="fixed">
    <origin rpy="0 0 0" xyz="0.0 0.0 0.0345"/>
    <parent link="head_tilt_bracket_link"/>
    <child link="camera_base_link"/>
  </joint>
  <link name="camera_base_link">
    <visual>
      <origin rpy="0 0 0" xyz="0 0.0 0.0"/>
      <geometry>
        <box size="0.072 0.085 0.021"/>
      </geometry>
      <material name="Black"/>
    </visual>
    <collision>
      <origin rpy="0 0 0" xyz="0 0 0"/>
      <geometry>
        <box size="0.072 0.085 0.021"/>
      </geometry>
    </collision>
  </link>
  <joint name="camera_base_post_joint" type="fixed">
    <origin rpy="0 0 0" xyz="0 0 0.0185"/>
    <parent link="camera_base_link"/>
    <child link="camera_base_post_link"/>
  </joint>
  <link name="camera_base_post_link">
    <visual>
      <origin rpy="0 0 0" xyz="0 0 0"/>
      <geometry>
        <cylinder length="0.016" radius="0.005"/>
      </geometry>
      <material name="Black"/>
    </visual>
    <collision>
      <origin rpy="0 0 0" xyz="0 0 0"/>
      <geometry>
        <cylinder length="0.016" radius="0.005"/>
      </geometry>
    </collision>
  </link>
  <joint name="camera_base_joint" type="fixed">
    <origin rpy="0 0 0" xyz="0 0 0.0245"/>
    <parent link="camera_base_post_link"/>
    <child link="camera_link"/>
  </joint>
  <link name="camera_link">
    <visual>
      <origin rpy="0 0 0" xyz="0 0 0"/>
      <geometry>
        <box size="0.07271 0.27794 0.033"/>
      </geometry>
      <material name="Black"/>
    </visual>
    <collision>
      <origin rpy="0 0 0" xyz="0 0 0"/>
      <geometry>
        <box size="0.07271 0.27794 0.033"/>
      </geometry>
    </collision>
  </link>
  <joint name="camera_depth_joint" type="fixed">
    <origin rpy="0 0 0" xyz="0 0.0125 0"/>
    <parent link="camera_link"/>
    <child link="camera_depth_frame"/>
  </joint>
  <link name="camera_depth_frame">
    <inertial>
      <mass value="0.000001"/>
      <origin xyz="0 0 0"/>
      <inertia ixx="0.0001" ixy="0.0" ixz="0.0" iyy="0.0001" iyz="0.0" izz="0.0001"/>
    </inertial>
  </link>
  <joint name="camera_depth_optical_joint" type="fixed">
    <origin rpy="-1.570795 0 -1.570795" xyz="0 0 0"/>
    <parent link="camera_depth_frame"/>
    <child link="camera_depth_optical_frame"/>
  </joint>
  <link name="camera_depth_optical_frame">
    <inertial>
      <mass value="0.000001"/>
      <origin xyz="0 0 0"/>
      <inertia ixx="0.0001" ixy="0.0" ixz="0.0" iyy="0.0001" iyz="0.0" izz="0.0001"/>
    </inertial>
  </link>
  <joint name="camera_rgb_joint" type="fixed">
    <origin rpy="0 0 0" xyz="0 -0.0125 0"/>
    <parent link="camera_link"/>
    <child link="camera_rgb_frame"/>
  </joint>
  <link name="camera_rgb_frame">
    <inertial>
      <mass value="0.000001"/>
      <origin xyz="0 0 0"/>
      <inertia ixx="0.0001" ixy="0.0" ixz="0.0" iyy="0.0001" iyz="0.0" izz="0.0001"/>
    </inertial>
  </link>
  <joint name="camera_rgb_optical_joint" type="fixed">
    <origin rpy="-1.570795 0 -1.570795" xyz="0 0 0"/>
    <parent link="camera_rgb_frame"/>
    <child link="camera_rgb_optical_frame"/>
  </joint>
  <link name="camera_rgb_optical_frame">
    <inertial>
      <mass value="0.000001"/>
      <origin xyz="0 0 0"/>
      <inertia ixx="0.0001" ixy="0.0" ixz="0.0" iyy="0.0001" iyz="0.0" izz="0.0001"/>
    </inertial>
  </link>
  <!-- Attach the right arm -->
  <link name="right_arm_base_link"/>
  <joint name="right_arm_base_joint" type="fixed">
    <origin rpy="0 0 1.570795" xyz="0.0 -0.05 0.2"/>
    <parent link="torso_link"/>
    <child link="right_arm_base_link"/>
  </joint>
  <joint name="right_arm_shoulder_F2_bracket_joint" type="fixed">
    <origin rpy="1.570795 0 1.570795" xyz="0 0 0"/>
    <parent link="right_arm_base_link"/>
    <child link="right_arm_shoulder_F2_bracket_link"/>
  </joint>
  <link name="right_arm_shoulder_F2_bracket_link">
    <inertial>
      <mass value="0.00001"/>
      <origin xyz="0 0 0"/>
      <inertia ixx="1.0" ixy="0.0" ixz="0.0" iyy="1.0" iyz="0.0" izz="1.0"/>
    </inertial>
    <visual>
      <origin rpy="0 0 0" xyz=" 0 0 0 "/>
      <geometry>
        <box size="0.0245 0.048 0.038"/>
      </geometry>
      <material name="White"/>
    </visual>
    <collision>
      <origin rpy="0 0 0" xyz="0.0 0.0 0.00775"/>
      <geometry>
        <box size="0.0245 0.048 0.038"/>
      </geometry>
    </collision>
  </link>
  <joint name="right_arm_shoulder_pan_joint" type="revolute">
    <origin rpy="0 0 0" xyz="0 0 -0.015"/>
    <axis xyz="0 1 0"/>
    <limit effort="1.0" lower="-2.7" upper="2.7" velocity="1.571"/>
    <parent link="right_arm_shoulder_F2_bracket_link"/>
    <child link="right_arm_shoulder_pan_link"/>
  </joint>
  <link name="right_arm_shoulder_pan_link">
    <inertial>
      <mass value="0.00001"/>
      <origin xyz="0 0 0"/>
      <inertia ixx="1.0" ixy="0.0" ixz="0.0" iyy="1.0" iyz="0.0" izz="1.0"/>
    </inertial>
    <visual>
      <origin rpy="0 0 0" xyz=" 0 0 0 "/>
      <geometry>
        <box size="0.0385 0.035 0.049"/>
      </geometry>
      <material name="Black"/>
    </visual>
    <collision>
      <origin rpy="0 0 0" xyz="0.0 0.0 -0.01241"/>
      <geometry>
        <box size="0.0385 0.035 0.049"/>
      </geometry>
    </collision>
  </link>
  <joint name="right_arm_shoulder_F3_bracket_joint" type="fixed">
    <origin rpy="0 3.14159 0" xyz="0 -0.01 -0.03275"/>
    <parent link="right_arm_shoulder_pan_link"/>
    <child link="right_arm_shoulder_F3_bracket_link"/>
  </joint>
  <link name="right_arm_shoulder_F3_bracket_link">
    <inertial>
      <mass value="0.00001"/>
      <origin xyz="0 0 0"/>
      <inertia ixx="1.0" ixy="0.0" ixz="0.0" iyy="1.0" iyz="0.0" izz="1.0"/>
    </inertial>
    <visual>
      <origin rpy="0 0 0" xyz=" 0 0 0 "/>
      <geometry>
        <box size="0.025 0.038 0.009"/>
      </geometry>
      <material name="White"/>
    </visual>
    <collision>
      <origin rpy="0 0 0" xyz="0.0 0.0 -0.0045"/>
      <geometry>
        <box size="0.025 0.038 0.009"/>
      </geometry>
    </collision>
  </link>
  <joint name="right_arm_shoulder_lift_joint" type="revolute">
    <origin rpy="1.570795 3.14159 3.14159" xyz="0 0 0.0175"/>
    <axis xyz="0 -1.0 0"/>
    <limit effort="1.0" lower="-4.7" upper="4.7" velocity="1.571"/>
    <parent link="right_arm_shoulder_F3_bracket_link"/>
    <child link="right_arm_shoulder_lift_link"/>
  </joint>
  <link name="right_arm_shoulder_lift_link">
    <inertial>
      <mass value="0.00001"/>
      <origin xyz="0 0 0"/>
      <inertia ixx="1.0" ixy="0.0" ixz="0.0" iyy="1.0" iyz="0.0" izz="1.0"/>
    </inertial>
    <visual>
      <origin rpy="0 0 0" xyz=" 0 0 0 "/>
      <geometry>
        <box size="0.0385 0.035 0.049"/>
      </geometry>
      <material name="Black"/>
    </visual>
    <collision>
      <origin rpy="0 0 0" xyz="0.0 0.0 -0.01241"/>
      <geometry>
        <box size="0.0385 0.035 0.049"/>
      </geometry>
    </collision>
  </link>
  <joint name="right_arm_shoulder_roll_joint" type="revolute">
    <origin rpy="1.570795 0 1.570795" xyz="-0.01 0 -0.049"/>
    <axis xyz="0 1.0 0"/>
    <limit effort="1.0" lower="-2.617" upper="2.617" velocity="1.571"/>
    <parent link="right_arm_shoulder_lift_link"/>
    <child link="right_arm_shoulder_roll_link"/>
  </joint>
  <link name="right_arm_shoulder_roll_link">
    <inertial>
      <mass value="0.00001"/>
      <origin xyz="0 0 0"/>
      <inertia ixx="1.0" ixy="0.0" ixz="0.0" iyy="1.0" iyz="0.0" izz="1.0"/>
    </inertial>
    <visual>
      <origin rpy="0 0 0" xyz=" 0 0 0 "/>
      <geometry>
        <box size="0.0385 0.035 0.049"/>
      </geometry>
      <material name="Black"/>
    </visual>
    <collision>
      <origin rpy="0 0 0" xyz="0.0 0.0 -0.01241"/>
      <geometry>
        <box size="0.0385 0.035 0.049"/>
      </geometry>
    </collision>
  </link>
  <joint name="right_arm_shoulder_roll_F3_bracket_joint" type="fixed">
    <origin rpy="0 1.570795 0" xyz="0.0175 0 0"/>
    <parent link="right_arm_shoulder_roll_link"/>
    <child link="right_arm_shoulder_roll_F3_bracket_link"/>
  </joint>
  <link name="right_arm_shoulder_roll_F3_bracket_link">
    <inertial>
      <mass value="0.00001"/>
      <origin xyz="0 0 0"/>
      <inertia ixx="1.0" ixy="0.0" ixz="0.0" iyy="1.0" iyz="0.0" izz="1.0"/>
    </inertial>
    <visual>
      <origin rpy="0 0 0" xyz=" 0 0 0 "/>
      <geometry>
        <box size="0.025 0.038 0.009"/>
      </geometry>
      <material name="White"/>
    </visual>
    <collision>
      <origin rpy="0 0 0" xyz="0.0 0.0 -0.0045"/>
      <geometry>
        <box size="0.025 0.038 0.009"/>
      </geometry>
    </collision>
  </link>
  <joint name="right_arm_shoulder_roll_F9_bracket_joint" type="fixed">
    <origin rpy="0 1.570795 0" xyz="0 -0.0125 -0.0085"/>
    <parent link="right_arm_shoulder_roll_F3_bracket_link"/>
    <child link="right_arm_shoulder_roll_F9_bracket_link"/>
  </joint>
  <link name="right_arm_shoulder_roll_F9_bracket_link">
    <inertial>
      <mass value="0.00001"/>
      <origin xyz="0 0 0"/>
      <inertia ixx="1.0" ixy="0.0" ixz="0.0" iyy="1.0" iyz="0.0" izz="1.0"/>
    </inertial>
    <visual>
      <origin rpy="0 0 0" xyz=" 0 0 0 "/>
      <geometry>
        <box size="0.025 0.025 0.025"/>
      </geometry>
      <material name="White"/>
    </visual>
    <collision>
      <origin rpy="0 0 0" xyz="0.0 0.0 -0.0045"/>
      <geometry>
        <box size="0.025 0.025 0.025"/>
      </geometry>
    </collision>
  </link>
  <joint name="right_arm_elbow_F3_bracket_joint" type="fixed">
    <origin rpy="1.570795 3.14159 3.14159" xyz="0.009 -0.01575 0"/>
    <parent link="right_arm_shoulder_roll_F9_bracket_link"/>
    <child link="right_arm_elbow_F3_bracket_link"/>
  </joint>
  <link name="right_arm_elbow_F3_bracket_link">
    <inertial>
      <mass value="0.00001"/>
      <origin xyz="0 0 0"/>
      <inertia ixx="1.0" ixy="0.0" ixz="0.0" iyy="1.0" iyz="0.0" izz="1.0"/>
    </inertial>
    <visual>
      <origin rpy="0 0 0" xyz=" 0 0 0 "/>
      <geometry>
        <box size="0.025 0.038 0.009"/>
      </geometry>
      <material name="White"/>
    </visual>
    <collision>
      <origin rpy="0 0 0" xyz="0.0 0.0 -0.0045"/>
      <geometry>
        <box size="0.025 0.038 0.009"/>
      </geometry>
    </collision>
  </link>
  <joint name="right_arm_elbow_flex_servo_joint" type="fixed">
    <origin rpy="0 3.14159 0" xyz="0 0 -0.029"/>
    <parent link="right_arm_elbow_F3_bracket_link"/>
    <child link="right_arm_elbow_flex_servo_link"/>
  </joint>
  <link name="right_arm_elbow_flex_servo_link">
    <inertial>
      <mass value="0.00001"/>
      <origin xyz="0 0 0"/>
      <inertia ixx="1.0" ixy="0.0" ixz="0.0" iyy="1.0" iyz="0.0" izz="1.0"/>
    </inertial>
    <visual>
      <origin rpy="0 0 0" xyz="0 0 0"/>
      <geometry>
        <box size="0.0385 0.035 0.049"/>
      </geometry>
      <material name="Black"/>
    </visual>
    <collision>
      <origin rpy="0 0 0" xyz="0 0 -0.01241"/>
      <geometry>
        <box size="0.0385 0.035 0.049"/>
      </geometry>
    </collision>
  </link>
  <joint name="right_arm_elbow_flex_joint" type="revolute">
    <origin rpy="0 0 0" xyz="0 0 0.0185"/>
    <axis xyz="0 1 0"/>
    <limit effort="1.0" lower="-1.8" upper="1.8" velocity="1.571"/>
    <parent link="right_arm_elbow_flex_servo_link"/>
    <child link="right_arm_elbow_flex_link"/>
  </joint>
  <link name="right_arm_elbow_flex_link">
    <inertial>
      <mass value="0.00001"/>
      <origin xyz="0 0 0"/>
      <inertia ixx="1.0" ixy="0.0" ixz="0.0" iyy="1.0" iyz="0.0" izz="1.0"/>
    </inertial>
    <visual>
      <origin rpy="0 0 0" xyz=" 0 0 0 "/>
      <geometry>
        <box size="0.0245 0.048 0.038"/>
      </geometry>
      <material name="White"/>
    </visual>
    <collision>
      <origin rpy="0 0 0" xyz="0.0 0.0 0.00775"/>
      <geometry>
        <box size="0.0245 0.048 0.038"/>
      </geometry>
    </collision>
  </link>
  <joint name="right_arm_forearm_F3_bracket_joint" type="fixed">
    <origin rpy="3.14159 0 1.570795" xyz="0 0 0.0235"/>
    <parent link="right_arm_elbow_flex_link"/>
    <child link="right_arm_forearm_F3_bracket_link"/>
  </joint>
  <link name="right_arm_forearm_F3_bracket_link">
    <inertial>
      <mass value="0.00001"/>
      <origin xyz="0 0 0"/>
      <inertia ixx="1.0" ixy="0.0" ixz="0.0" iyy="1.0" iyz="0.0" izz="1.0"/>
    </inertial>
    <visual>
      <origin rpy="0 0 0" xyz=" 0 0 0 "/>
      <geometry>
        <box size="0.025 0.038 0.009"/>
      </geometry>
      <material name="White"/>
    </visual>
    <collision>
      <origin rpy="0 0 0" xyz="0.0 0.0 -0.0045"/>
      <geometry>
        <box size="0.025 0.038 0.009"/>
      </geometry>
    </collision>
  </link>
  <joint name="right_arm_forearm_flex_servo_joint" type="fixed">
    <origin rpy="3.14159 0 0" xyz="0 0 -0.02875"/>
    <parent link="right_arm_forearm_F3_bracket_link"/>
    <child link="right_arm_forearm_flex_servo_link"/>
  </joint>
  <link name="right_arm_forearm_flex_servo_link">
    <inertial>
      <mass value="0.00001"/>
      <origin xyz="0 0 0"/>
      <inertia ixx="1.0" ixy="0.0" ixz="0.0" iyy="1.0" iyz="0.0" izz="1.0"/>
    </inertial>
    <visual>
      <origin rpy="0 0 0" xyz="0 0 0"/>
      <geometry>
        <box size="0.0385 0.035 0.049"/>
      </geometry>
      <material name="Black"/>
    </visual>
    <collision>
      <origin rpy="0 0 0" xyz="0 0 -0.01241"/>
      <geometry>
        <box size="0.0385 0.035 0.049"/>
      </geometry>
    </collision>
  </link>
  <joint name="right_arm_forearm_flex_joint" type="revolute">
    <origin rpy="0 0 0" xyz="0 0 0.0245"/>
    <axis xyz="0 1.0 0"/>
    <limit effort="1.0" lower="-1.8" upper="1.8" velocity="1.571"/>
    <parent link="right_arm_forearm_flex_servo_link"/>
    <child link="right_arm_forearm_flex_link"/>
  </joint>
  <link name="right_arm_forearm_flex_link">
    <inertial>
      <mass value="0.00001"/>
      <origin xyz="0 0 0"/>
      <inertia ixx="1.0" ixy="0.0" ixz="0.0" iyy="1.0" iyz="0.0" izz="1.0"/>
    </inertial>
    <visual>
      <origin rpy="0 0 0" xyz=" 0 0 0 "/>
      <geometry>
        <box size="0.0245 0.048 0.038"/>
      </geometry>
      <material name="White"/>
    </visual>
    <collision>
      <origin rpy="0 0 0" xyz="0.0 0.0 0.00775"/>
      <geometry>
        <box size="0.0245 0.048 0.038"/>
      </geometry>
    </collision>
  </link>
  <joint name="right_arm_forearm_F2_bracket_joint" type="fixed">
    <origin rpy="0 3.14159 1.570795" xyz="0 0 0.03825"/>
    <parent link="right_arm_forearm_flex_link"/>
    <child link="right_arm_forearm_F2_bracket_link"/>
  </joint>
  <link name="right_arm_forearm_F2_bracket_link">
    <inertial>
      <mass value="0.00001"/>
      <origin xyz="0 0 0"/>
      <inertia ixx="1.0" ixy="0.0" ixz="0.0" iyy="1.0" iyz="0.0" izz="1.0"/>
    </inertial>
    <visual>
      <origin rpy="0 0 0" xyz=" 0 0 0 "/>
      <geometry>
        <box size="0.0245 0.048 0.038"/>
      </geometry>
      <material name="White"/>
    </visual>
    <collision>
      <origin rpy="0 0 0" xyz="0.0 0.0 0.00775"/>
      <geometry>
        <box size="0.0245 0.048 0.038"/>
      </geometry>
    </collision>
  </link>
  <joint name="right_arm_wrist_flex_joint" type="revolute">
    <origin rpy="0 0 0" xyz="0 0 -0.0225"/>
    <axis xyz="0 1 0"/>
    <limit effort="1.0" lower="-1.57" upper="1.57" velocity="1.571"/>
    <parent link="right_arm_forearm_F2_bracket_link"/>
    <child link="right_arm_wrist_flex_link"/>
  </joint>
  <link name="right_arm_wrist_flex_link">
    <inertial>
      <mass value="0.00001"/>
      <origin xyz="0 0 0"/>
      <inertia ixx="1.0" ixy="0.0" ixz="0.0" iyy="1.0" iyz="0.0" izz="1.0"/>
    </inertial>
    <visual>
      <origin rpy="0 0 0" xyz=" 0 0 0 "/>
      <geometry>
        <box size="0.0385 0.035 0.049"/>
      </geometry>
      <material name="Black"/>
    </visual>
    <collision>
      <origin rpy="0 0 0" xyz="0.0 0.0 -0.01241"/>
      <geometry>
        <box size="0.0385 0.035 0.049"/>
      </geometry>
    </collision>
  </link>
  <joint name="right_arm_wrist_F3_bracket_joint" type="fixed">
    <origin rpy="3.14159 0 0" xyz="0 0 -0.029"/>
    <parent link="right_arm_wrist_flex_link"/>
    <child link="right_arm_wrist_F3_bracket_link"/>
  </joint>
  <link name="right_arm_wrist_F3_bracket_link">
    <inertial>
      <mass value="0.00001"/>
      <origin xyz="0 0 0"/>
      <inertia ixx="1.0" ixy="0.0" ixz="0.0" iyy="1.0" iyz="0.0" izz="1.0"/>
    </inertial>
    <visual>
      <origin rpy="0 0 0" xyz=" 0 0 0 "/>
      <geometry>
        <box size="0.025 0.038 0.009"/>
      </geometry>
      <material name="White"/>
    </visual>
    <collision>
      <origin rpy="0 0 0" xyz="0.0 0.0 -0.0045"/>
      <geometry>
        <box size="0.025 0.038 0.009"/>
      </geometry>
    </collision>
  </link>
  <joint name="right_arm_gripper_attach_joint" type="fixed">
    <origin rpy="3.14159 0 0" xyz="0 0 0.009"/>
    <parent link="right_arm_wrist_F3_bracket_link"/>
    <child link="right_arm_gripper_attach_link"/>
  </joint>
  <link name="right_arm_gripper_attach_link">
    <inertial>
      <mass value="0.00001"/>
      <origin xyz="0 0 0"/>
      <inertia ixx="1.0" ixy="0.0" ixz="0.0" iyy="1.0" iyz="0.0" izz="1.0"/>
    </inertial>
    <visual>
      <origin rpy="0 0 0" xyz=" 0 0 0 "/>
      <geometry>
        <box size="0.025 0.038 0.009"/>
      </geometry>
      <material name="White"/>
    </visual>
    <collision>
      <origin rpy="0 0 0" xyz="0.0 0.0 -0.0045"/>
      <geometry>
        <box size="0.025 0.038 0.009"/>
      </geometry>
    </collision>
  </link>
  <!-- Attach the right gripper -->
  <joint name="right_gripper_base_joint" type="fixed">
    <origin rpy="0 1.570795 3.14159" xyz="0 0 -0.0235"/>
    <parent link="right_arm_gripper_attach_link"/>
    <child link="right_gripper_base_link"/>
  </joint>
  <link name="right_gripper_base_link">
    <inertial>
      <mass value="0.00001"/>
      <origin xyz="0 0 0"/>
      <inertia ixx="1.0" ixy="0.0" ixz="0.0" iyy="1.0" iyz="0.0" izz="1.0"/>
    </inertial>
    <visual>
      <origin rpy="0 0 0" xyz="0 0 0"/>
      <geometry>
        <box size="0.0385 0.035 0.049"/>
      </geometry>
      <material name="Black"/>
    </visual>
    <collision>
      <origin rpy="0 0 0" xyz="0 0 -0.01241"/>
      <geometry>
        <box size="0.0385 0.035 0.049"/>
      </geometry>
    </collision>
  </link>
  <joint name="right_gripper_finger_joint" type="revolute">
    <origin rpy="0 0 0" xyz="0 0 0.025"/>
    <axis xyz="0 1 0"/>
    <limit effort="30" lower="-0.060" upper="0.50" velocity="0.785"/>
    <parent link="right_gripper_base_link"/>
    <child link="right_gripper_active_finger_bracket_link"/>
  </joint>
  <link name="right_gripper_active_finger_bracket_link">
    <inertial>
      <mass value="0.00001"/>
      <origin xyz="0 0 0"/>
      <inertia ixx="1.0" ixy="0.0" ixz="0.0" iyy="1.0" iyz="0.0" izz="1.0"/>
    </inertial>
    <visual>
      <origin rpy="0 0 0" xyz="0 0 0"/>
      <geometry>
        <box size="0.0245 0.048 0.038"/>
      </geometry>
      <material name="Green"/>
    </visual>
    <collision>
      <origin rpy="0 0 0" xyz="0.0 0.0 0.00775"/>
      <geometry>
        <box size="0.0245 0.048 0.038"/>
      </geometry>
    </collision>
  </link>
  <joint name="right_gripper_active_finger_joint" type="fixed">
    <origin rpy="0 0 0" xyz="0 0 0.019"/>
    <parent link="right_gripper_active_finger_bracket_link"/>
    <child link="right_gripper_active_finger_link"/>
  </joint>
  <link name="right_gripper_active_finger_link">
    <inertial>
      <mass value="0.00001"/>
      <origin xyz="0 0 0"/>
      <inertia ixx="1.0" ixy="0.0" ixz="0.0" iyy="1.0" iyz="0.0" izz="1.0"/>
    </inertial>
    <visual>
      <origin rpy="0 0 0" xyz=" 0 0 0 "/>
      <geometry>
        <mesh filename="package://rbx2_description/meshes/finger.stl" scale="0.001 0.001 0.001"/>
      </geometry>
      <material name="Green"/>
    </visual>
    <collision>
      <origin rpy="0 0 0" xyz="0.02645 0.0 -0.00655"/>
      <geometry>
        <box size="0.0783 0.03801 0.0193"/>
      </geometry>
    </collision>
  </link>
  <joint name="right_gripper_static_finger_bracket_joint" type="fixed">
    <origin rpy="0 3.14159 0" xyz="0 0 -0.029"/>
    <parent link="right_gripper_base_link"/>
    <child link="right_gripper_static_finger_bracket_link"/>
  </joint>
  <link name="right_gripper_static_finger_bracket_link">
    <inertial>
      <mass value="0.00001"/>
      <origin xyz="0 0 0"/>
      <inertia ixx="1.0" ixy="0.0" ixz="0.0" iyy="1.0" iyz="0.0" izz="1.0"/>
    </inertial>
    <visual>
      <origin rpy="0 0 0" xyz=" 0 0 0 "/>
      <geometry>
        <box size="0.025 0.038 0.009"/>
      </geometry>
      <material name="Green"/>
    </visual>
    <collision>
      <origin rpy="0 0 0" xyz="0.0 0.0 -0.0045"/>
      <geometry>
        <box size="0.025 0.038 0.009"/>
      </geometry>
    </collision>
  </link>
  <joint name="right_gripper_static_finger_joint" type="fixed">
    <origin rpy="0 0 3.14159" xyz="0 0 0.004"/>
    <parent link="right_gripper_static_finger_bracket_link"/>
    <child link="right_gripper_static_finger_link"/>
  </joint>
  <link name="right_gripper_static_finger_link">
    <inertial>
      <mass value="0.00001"/>
      <origin xyz="0 0 0"/>
      <inertia ixx="1.0" ixy="0.0" ixz="0.0" iyy="1.0" iyz="0.0" izz="1.0"/>
    </inertial>
    <visual>
      <origin rpy="0 0 0" xyz=" 0 0 0 "/>
      <geometry>
        <mesh filename="package://rbx2_description/meshes/finger.stl" scale="0.001 0.001 0.001"/>
      </geometry>
      <material name="Green"/>
    </visual>
    <collision>
      <origin rpy="0 0 0" xyz="0.02645 0.0 -0.00655"/>
      <geometry>
        <box size="0.0783 0.03801 0.0193"/>
      </geometry>
    </collision>
  </link>
  <joint name="right_gripper_joint" type="fixed">
    <axis xyz="0 0 1"/>
    <origin rpy="1.570795 0 0" xyz="0.05 0.0 -0.0375"/>
    <parent link="right_gripper_static_finger_link"/>
    <child link="right_gripper_link"/>
  </joint>
  <link name="right_gripper_link">
    <visual>
      <origin rpy="0 0 0" xyz="0 0 0"/>
      <geometry>
        <box size="0.001 0.0005 0.0005"/>
      </geometry>
    </visual>
  </link>
</robot>

