<?xml version="1.0" ?>
<!-- =================================================================================== -->
<!-- |    This document was autogenerated by xacro from pi_robot_with_arm.xacro        | -->
<!-- |    EDITING THIS FILE BY HAND IS NOT RECOMMENDED                                 | -->
<!-- =================================================================================== -->
<robot name="pi_robot" xmlns:xacro="http://ros.org/wiki/xacro">
  <!-- Define a number of dimensions using properties -->
  <!-- The following xacro:include files set up definitions of parts of the robot body -->
  <material name="Black">
    <color rgba="0.2 0.2 0.2 1.0"/>
  </material>
  <material name="TransparentBlack">
    <color rgba="0.2 0.2 0.2 0.8"/>
  </material>
  <material name="Orange">
    <color rgba="1.0  0.55 0.0 1.0"/>
  </material>
  <material name="Grey">
    <color rgba="0.7 0.7 0.7 1.0"/>
  </material>
  <material name="DarkGrey">
    <color rgba="0.3 0.3 0.3 1.0"/>
  </material>
  <material name="Red">
    <color rgba="0.8 0.0 0.0 1.0"/>
  </material>
  <material name="White">
    <color rgba="1.0 1.0 1.0 1.0"/>
  </material>
  <material name="OffWhite">
    <color rgba="0.8 0.8 0.8 1.0"/>
  </material>
  <material name="Blue">
    <color rgba="0.0 0.0 0.8 1.0"/>
  </material>
  <material name="Green">
    <color rgba="0.0 0.8 0.0 1.0"/>
  </material>
  <material name="TransparentGreen">
    <color rgba="0.0 0.8 0.0 0.5"/>
  </material>
  <link name="base_footprint">
    <visual>
      <origin rpy="0 0 0" xyz="0 0 0"/>
      <geometry>
        <box size="0.05 0.05 0.001"/>
      </geometry>
      <material name="TransparentGreen"/>
    </visual>
  </link>
  <joint name="base_joint" type="fixed">
    <origin rpy="0 0 0" xyz="0 0 0.06541"/>
    <parent link="base_footprint"/>
    <child link="base_link"/>
  </joint>
  <joint name="base_l_wheel_joint" type="continuous">
    <axis xyz="0 0 1"/>
    <limit effort="100" velocity="100"/>
    <safety_controller k_velocity="10"/>
    <origin rpy="1.57 0 0" xyz="0.07 0.13 -0.0035"/>
    <parent link="base_link"/>
    <child link="base_l_wheel_link"/>
  </joint>
  <link name="base_l_wheel_link">
    <visual>
      <origin rpy="0 0 0" xyz="0 0 0"/>
      <geometry>
        <cylinder length="0.02032" radius="0.06191"/>
      </geometry>
      <material name="Orange"/>
    </visual>
  </link>
  <joint name="base_r_wheel_joint" type="continuous">
    <axis xyz="0 0 1"/>
    <limit effort="100" velocity="100"/>
    <safety_controller k_velocity="10"/>
    <origin rpy="-1.57 0 0" xyz="0.07 -0.13 -0.0035"/>
    <parent link="base_link"/>
    <child link="base_r_wheel_link"/>
  </joint>
  <link name="base_r_wheel_link">
    <visual>
      <origin rpy="0 0 0" xyz="0 0 0"/>
      <geometry>
        <cylinder length="0.02032" radius="0.06191"/>
      </geometry>
      <material name="Orange"/>
    </visual>
  </link>
  <!-- Now we can start using the macros included above to define the actual robot -->
  <!-- Start with the base and wheels -->
  <link name="base_link">
    <visual>
      <origin rpy="0 0 1.570795" xyz="0 0 0"/>
      <geometry>
        <mesh filename="package://rbx2_description/meshes/pi_robot/pi_robot_base.stl" scale="0.0254 0.0254 0.0254"/>
      </geometry>
      <material name="Black"/>
    </visual>
    <collision>
      <origin rpy="0 0 0" xyz="0 0 0.1205"/>
      <geometry>
        <cylinder length="0.241" radius="0.152"/>
      </geometry>
    </collision>
  </link>
  <!-- Attach the torso -->
  <joint name="base_torso_joint" type="fixed">
    <origin rpy="0 0 0" xyz="-0.13 0.0 0.088"/>
    <parent link="base_link"/>
    <child link="torso_link"/>
  </joint>
  <link name="torso_link">
    <visual>
      <origin rpy="0 0 0" xyz="0 0 0"/>
      <geometry>
        <mesh filename="package://rbx2_description/meshes/pi_robot/t_slot.stl" scale="0.0127 0.0127 0.0127"/>
      </geometry>
      <material name="Grey"/>
    </visual>
    <collision>
      <origin rpy="0 0 0" xyz="0 0 0.4425"/>
      <geometry>
        <box size="0.025 0.025 0.885"/>
      </geometry>
    </collision>
  </link>
  <!-- Attach the pan and tilt head -->
  <joint name="head_base_joint" type="fixed">
    <origin rpy="1.570795 0 1.570795" xyz="0.0595 0.0036 0.845"/>
    <parent link="torso_link"/>
    <child link="head_base_link"/>
  </joint>
  <link name="head_base_link">
    <origin rpy="0 0 0" xyz="0 0 0"/>
    <inertial>
      <mass value="0.00001"/>
      <inertia ixx="1.0" ixy="0.0" ixz="0.0" iyy="1.0" iyz="0.0" izz="1.0"/>
    </inertial>
    <visual>
      <origin rpy="0 0 0" xyz="0 0 0 "/>
      <geometry>
        <cylinder length="0.00001" radius="0.01"/>
      </geometry>
    </visual>
    <collision>
      <origin rpy="0 0 0" xyz="0 0 0 "/>
      <geometry>
        <cylinder length="0.00001" radius="0.01"/>
      </geometry>
    </collision>
  </link>
  <joint name="head_pan_servo_joint" type="fixed">
    <origin rpy="0 0 0" xyz="0 0 0"/>
    <parent link="head_base_link"/>
    <child link="head_pan_servo_link"/>
  </joint>
  <link name="head_pan_servo_link">
    <inertial>
      <mass value="0.00001"/>
      <origin xyz="0 0 0"/>
      <inertia ixx="1.0" ixy="0.0" ixz="0.0" iyy="1.0" iyz="0.0" izz="1.0"/>
    </inertial>
    <visual>
      <origin rpy="0 0 0" xyz=" 0 0 0 "/>
      <geometry>
        <mesh filename="package://rbx2_description/meshes/ax12.stl" scale="0.001 0.001 0.001"/>
      </geometry>
      <material name="Black"/>
    </visual>
    <collision>
      <origin rpy="0 0 0" xyz="0.0 0.0 -0.01241"/>
      <geometry>
        <box size="0.025 0.038 0.04762"/>
      </geometry>
    </collision>
  </link>
  <joint name="head_pan_joint" type="revolute">
    <origin rpy="-1.570795 1.570795 3.14159" xyz="0 0.0225 0"/>
    <parent link="head_pan_servo_link"/>
    <axis xyz="0 0 -1"/>
    <limit effort="1.0" lower="-2.53" upper="2.53" velocity="1.571"/>
    <child link="head_pan_bracket_link"/>
  </joint>
  <link name="head_pan_bracket_link">
    <inertial>
      <mass value="0.00001"/>
      <origin xyz="0 0 0"/>
      <inertia ixx="1.0" ixy="0.0" ixz="0.0" iyy="1.0" iyz="0.0" izz="1.0"/>
    </inertial>
    <visual>
      <origin rpy="0 0 0" xyz="0 0 0 "/>
      <geometry>
        <mesh filename="package://rbx2_description/meshes/F3.stl" scale="0.001 0.001 0.001"/>
      </geometry>
      <material name="White"/>
    </visual>
    <collision>
      <origin rpy="0 0 0" xyz="0 0 0"/>
      <geometry>
        <box size="0.025 0.038 0.009"/>
      </geometry>
    </collision>
  </link>
  <joint name="head_tilt_servo_joint" type="fixed">
    <origin rpy="0 3.14159 0" xyz="0 0 -0.0415"/>
    <parent link="head_pan_bracket_link"/>
    <child link="head_tilt_servo_link"/>
  </joint>
  <link name="head_tilt_servo_link">
    <inertial>
      <mass value="0.00001"/>
      <origin xyz="0 0 0"/>
      <inertia ixx="1.0" ixy="0.0" ixz="0.0" iyy="1.0" iyz="0.0" izz="1.0"/>
    </inertial>
    <visual>
      <origin rpy="0 0 0" xyz=" 0 0 0 "/>
      <geometry>
        <mesh filename="package://rbx2_description/meshes/ax12.stl" scale="0.001 0.001 0.001"/>
      </geometry>
      <material name="Black"/>
    </visual>
    <collision>
      <origin rpy="0 0 0" xyz="0.0 0.0 -0.01241"/>
      <geometry>
        <box size="0.025 0.038 0.04762"/>
      </geometry>
    </collision>
  </link>
  <joint name="head_tilt_joint" type="revolute">
    <origin rpy="0 0 0" xyz="0 0 0"/>
    <parent link="head_tilt_servo_link"/>
    <axis xyz="0 1 0"/>
    <limit effort="1.0" lower="-2.53" upper="2.53" velocity="1.571"/>
    <child link="head_tilt_bracket_link"/>
  </joint>
  <link name="head_tilt_bracket_link">
    <inertial>
      <mass value="0.00001"/>
      <origin xyz="0 0 0"/>
      <inertia ixx="1.0" ixy="0.0" ixz="0.0" iyy="1.0" iyz="0.0" izz="1.0"/>
    </inertial>
    <visual>
      <origin rpy="0 0 0" xyz="0 0 0 "/>
      <geometry>
        <mesh filename="package://rbx2_description/meshes/F2.stl" scale="0.001 0.001 0.001"/>
      </geometry>
      <material name="White"/>
    </visual>
    <collision>
      <origin rpy="0 0 0" xyz="0 0 0"/>
      <geometry>
        <box size="0.0245 0.038 0.048"/>
      </geometry>
    </collision>
  </link>
  <joint name="head_tilt_bracket_camera_joint" type="fixed">
    <origin rpy="0 0 0" xyz="0.0 0.0 0.0615"/>
    <parent link="head_tilt_bracket_link"/>
    <child link="camera_link"/>
  </joint>
  <link name="camera_link">
    <visual>
      <origin rpy="0 0 1.570795" xyz="0 0 0"/>
      <geometry>
        <mesh filename="package://rbx2_description/meshes/kinect.dae" scale="1.0 1.0 1.0"/>
      </geometry>
      <material name="Black"/>
    </visual>
    <collision>
      <origin rpy="0 0 0" xyz="0 0 0"/>
      <geometry>
        <box size="0.07271 0.27794 0.07"/>
      </geometry>
    </collision>
  </link>
  <joint name="camera_depth_joint" type="fixed">
    <origin rpy="0 0 0" xyz="0 0.0125 0.015"/>
    <parent link="camera_link"/>
    <child link="camera_depth_frame"/>
  </joint>
  <link name="camera_depth_frame">
    <inertial>
      <mass value="0.000001"/>
      <origin xyz="0 0 0"/>
      <inertia ixx="0.0001" ixy="0.0" ixz="0.0" iyy="0.0001" iyz="0.0" izz="0.0001"/>
    </inertial>
  </link>
  <joint name="camera_depth_optical_joint" type="fixed">
    <origin rpy="-1.570795 0 -1.570795" xyz="0 0 0"/>
    <parent link="camera_depth_frame"/>
    <child link="camera_depth_optical_frame"/>
  </joint>
  <link name="camera_depth_optical_frame">
    <inertial>
      <mass value="0.000001"/>
      <origin xyz="0 0 0"/>
      <inertia ixx="0.0001" ixy="0.0" ixz="0.0" iyy="0.0001" iyz="0.0" izz="0.0001"/>
    </inertial>
  </link>
  <joint name="camera_rgb_joint" type="fixed">
    <origin rpy="0 0 0" xyz="0 -0.0125 0.015"/>
    <parent link="camera_link"/>
    <child link="camera_rgb_frame"/>
  </joint>
  <link name="camera_rgb_frame">
    <inertial>
      <mass value="0.000001"/>
      <origin xyz="0 0 0"/>
      <inertia ixx="0.0001" ixy="0.0" ixz="0.0" iyy="0.0001" iyz="0.0" izz="0.0001"/>
    </inertial>
  </link>
  <joint name="camera_rgb_optical_joint" type="fixed">
    <origin rpy="-1.570795 0 -1.570795" xyz="0 0 0"/>
    <parent link="camera_rgb_frame"/>
    <child link="camera_rgb_optical_frame"/>
  </joint>
  <link name="camera_rgb_optical_frame">
    <inertial>
      <mass value="0.000001"/>
      <origin xyz="0 0 0"/>
      <inertia ixx="0.0001" ixy="0.0" ixz="0.0" iyy="0.0001" iyz="0.0" izz="0.0001"/>
    </inertial>
  </link>
  <!-- Attach the right arm -->
  <link name="right_arm_base_link"/>
  <joint name="right_arm_base_joint" type="fixed">
    <origin rpy="0 0 1.570795" xyz="0.01 -0.05 0.7"/>
    <parent link="torso_link"/>
    <child link="right_arm_base_link"/>
  </joint>
  <joint name="right_arm_shoulder_F2_0_joint" type="fixed">
    <origin rpy="1.570795 0 1.570795" xyz="0 0 0"/>
    <parent link="right_arm_base_link"/>
    <child link="right_arm_shoulder_F2_0_link"/>
  </joint>
  <link name="right_arm_shoulder_F2_0_link">
    <inertial>
      <mass value="0.00001"/>
      <origin xyz="0 0 0"/>
      <inertia ixx="1.0" ixy="0.0" ixz="0.0" iyy="1.0" iyz="0.0" izz="1.0"/>
    </inertial>
    <visual>
      <origin rpy="0 0 0" xyz=" 0 0 0 "/>
      <geometry>
        <mesh filename="package://rbx2_description/meshes/F2.stl" scale="0.001 0.001 0.001"/>
      </geometry>
      <material name="White"/>
    </visual>
    <collision>
      <origin rpy="0 0 0" xyz="0.0 0.0 0.00775"/>
      <geometry>
        <box size="0.025 0.0485 0.0375"/>
      </geometry>
    </collision>
  </link>
  <joint name="right_arm_shoulder_pan_joint" type="revolute">
    <origin rpy="0 0 0" xyz="0 0 0"/>
    <axis xyz="0 1 0"/>
    <limit effort="1.0" lower="-2.09" upper="2.09" velocity="3.14"/>
    <parent link="right_arm_shoulder_F2_0_link"/>
    <child link="right_arm_shoulder_pan_link"/>
  </joint>
  <link name="right_arm_shoulder_pan_link">
    <inertial>
      <mass value="0.00001"/>
      <origin xyz="0 0 0"/>
      <inertia ixx="1.0" ixy="0.0" ixz="0.0" iyy="1.0" iyz="0.0" izz="1.0"/>
    </inertial>
    <visual>
      <origin rpy="0 0 0" xyz=" 0 0 0 "/>
      <geometry>
        <mesh filename="package://rbx2_description/meshes/ax12.stl" scale="0.001 0.001 0.001"/>
      </geometry>
      <material name="Black"/>
    </visual>
    <collision>
      <origin rpy="0 0 0" xyz="0.0 0.0 -0.01241"/>
      <geometry>
        <box size="0.025 0.038 0.04762"/>
      </geometry>
    </collision>
  </link>
  <joint name="right_arm_shoulder_F3_0_joint" type="fixed">
    <origin rpy="0 3.14159 0" xyz="0 0 -0.0405"/>
    <parent link="right_arm_shoulder_pan_link"/>
    <child link="right_arm_shoulder_F3_0_link"/>
  </joint>
  <link name="right_arm_shoulder_F3_0_link">
    <inertial>
      <mass value="0.00001"/>
      <origin xyz="0 0 0"/>
      <inertia ixx="1.0" ixy="0.0" ixz="0.0" iyy="1.0" iyz="0.0" izz="1.0"/>
    </inertial>
    <visual>
      <origin rpy="0 0 0" xyz=" 0 0 0 "/>
      <geometry>
        <mesh filename="package://rbx2_description/meshes/F3.stl" scale="0.001 0.001 0.001"/>
      </geometry>
      <material name="White"/>
    </visual>
    <collision>
      <origin rpy="0 0 0" xyz="0.0 0.0 -0.0045"/>
      <geometry>
        <box size="0.025 0.038 0.009"/>
      </geometry>
    </collision>
  </link>
  <joint name="right_arm_shoulder_lift_joint" type="revolute">
    <origin rpy="1.570795 3.14159 3.14159" xyz="0 0.002 0.0175"/>
    <axis xyz="0 1 0"/>
    <limit effort="1.0" lower="-3.14" upper="3.14" velocity="3.14"/>
    <parent link="right_arm_shoulder_F3_0_link"/>
    <child link="right_arm_shoulder_lift_link"/>
  </joint>
  <link name="right_arm_shoulder_lift_link">
    <inertial>
      <mass value="0.00001"/>
      <origin xyz="0 0 0"/>
      <inertia ixx="1.0" ixy="0.0" ixz="0.0" iyy="1.0" iyz="0.0" izz="1.0"/>
    </inertial>
    <visual>
      <origin rpy="0 0 0" xyz=" 0 0 0 "/>
      <geometry>
        <mesh filename="package://rbx2_description/meshes/ax12.stl" scale="0.001 0.001 0.001"/>
      </geometry>
      <material name="Black"/>
    </visual>
    <collision>
      <origin rpy="0 0 0" xyz="0.0 0.0 -0.01241"/>
      <geometry>
        <box size="0.025 0.038 0.04762"/>
      </geometry>
    </collision>
  </link>
  <joint name="right_arm_shoulder_F3_1_joint" type="fixed">
    <origin rpy="3.14159 0 0" xyz="0 0 -0.0405"/>
    <parent link="right_arm_shoulder_lift_link"/>
    <child link="right_arm_shoulder_F3_1_link"/>
  </joint>
  <link name="right_arm_shoulder_F3_1_link">
    <inertial>
      <mass value="0.00001"/>
      <origin xyz="0 0 0"/>
      <inertia ixx="1.0" ixy="0.0" ixz="0.0" iyy="1.0" iyz="0.0" izz="1.0"/>
    </inertial>
    <visual>
      <origin rpy="0 0 0" xyz=" 0 0 0 "/>
      <geometry>
        <mesh filename="package://rbx2_description/meshes/F3.stl" scale="0.001 0.001 0.001"/>
      </geometry>
      <material name="White"/>
    </visual>
    <collision>
      <origin rpy="0 0 0" xyz="0.0 0.0 -0.0045"/>
      <geometry>
        <box size="0.025 0.038 0.009"/>
      </geometry>
    </collision>
  </link>
  <joint name="right_arm_shoulder_roll_joint" type="revolute">
    <origin rpy="-1.570795 0 -1.570795" xyz="0 0 0.01925"/>
    <axis xyz="0 1 0"/>
    <limit effort="1.0" lower="-3.14" upper="3.14" velocity="3.14"/>
    <parent link="right_arm_shoulder_F3_1_link"/>
    <child link="right_arm_shoulder_roll_link"/>
  </joint>
  <link name="right_arm_shoulder_roll_link">
    <inertial>
      <mass value="0.00001"/>
      <origin xyz="0 0 0"/>
      <inertia ixx="1.0" ixy="0.0" ixz="0.0" iyy="1.0" iyz="0.0" izz="1.0"/>
    </inertial>
    <visual>
      <origin rpy="0 0 0" xyz=" 0 0 0 "/>
      <geometry>
        <mesh filename="package://rbx2_description/meshes/ax12.stl" scale="0.001 0.001 0.001"/>
      </geometry>
      <material name="Black"/>
    </visual>
    <collision>
      <origin rpy="0 0 0" xyz="0.0 0.0 -0.01241"/>
      <geometry>
        <box size="0.025 0.038 0.04762"/>
      </geometry>
    </collision>
  </link>
  <joint name="right_arm_shoulder_roll_F3_0_joint" type="fixed">
    <origin rpy="0 1.570795 0" xyz="0.0175 0 -0.0055"/>
    <parent link="right_arm_shoulder_roll_link"/>
    <child link="right_arm_shoulder_roll_F3_0_link"/>
  </joint>
  <link name="right_arm_shoulder_roll_F3_0_link">
    <inertial>
      <mass value="0.00001"/>
      <origin xyz="0 0 0"/>
      <inertia ixx="1.0" ixy="0.0" ixz="0.0" iyy="1.0" iyz="0.0" izz="1.0"/>
    </inertial>
    <visual>
      <origin rpy="0 0 0" xyz=" 0 0 0 "/>
      <geometry>
        <mesh filename="package://rbx2_description/meshes/F3.stl" scale="0.001 0.001 0.001"/>
      </geometry>
      <material name="White"/>
    </visual>
    <collision>
      <origin rpy="0 0 0" xyz="0.0 0.0 -0.0045"/>
      <geometry>
        <box size="0.025 0.038 0.009"/>
      </geometry>
    </collision>
  </link>
  <joint name="right_arm_shoulder_roll_F9_0_joint" type="fixed">
    <origin rpy="0 1.570795 0" xyz="0 -0.0125 -0.0085"/>
    <parent link="right_arm_shoulder_roll_F3_0_link"/>
    <child link="right_arm_shoulder_roll_F9_0_link"/>
  </joint>
  <link name="right_arm_shoulder_roll_F9_0_link">
    <inertial>
      <mass value="0.00001"/>
      <origin xyz="0 0 0"/>
      <inertia ixx="1.0" ixy="0.0" ixz="0.0" iyy="1.0" iyz="0.0" izz="1.0"/>
    </inertial>
    <visual>
      <origin rpy="0 0 0" xyz=" 0 0 0 "/>
      <geometry>
        <mesh filename="package://rbx2_description/meshes/F9.stl" scale="0.001 0.001 0.001"/>
      </geometry>
      <material name="White"/>
    </visual>
    <collision>
      <origin rpy="0 0 0" xyz="0.0 0.0 -0.0045"/>
      <geometry>
        <box size="0.025 0.030 0.025"/>
      </geometry>
    </collision>
  </link>
  <joint name="right_arm_elbow_F3_0_joint" type="fixed">
    <origin rpy="1.570795 3.14159 3.14159" xyz="0 -0.01575 0"/>
    <parent link="right_arm_shoulder_roll_F9_0_link"/>
    <child link="right_arm_elbow_F3_0_link"/>
  </joint>
  <link name="right_arm_elbow_F3_0_link">
    <inertial>
      <mass value="0.00001"/>
      <origin xyz="0 0 0"/>
      <inertia ixx="1.0" ixy="0.0" ixz="0.0" iyy="1.0" iyz="0.0" izz="1.0"/>
    </inertial>
    <visual>
      <origin rpy="0 0 0" xyz=" 0 0 0 "/>
      <geometry>
        <mesh filename="package://rbx2_description/meshes/F3.stl" scale="0.001 0.001 0.001"/>
      </geometry>
      <material name="White"/>
    </visual>
    <collision>
      <origin rpy="0 0 0" xyz="0.0 0.0 -0.0045"/>
      <geometry>
        <box size="0.025 0.038 0.009"/>
      </geometry>
    </collision>
  </link>
  <joint name="right_arm_elbow_flex_servo_joint" type="fixed">
    <origin rpy="0 3.14159 0" xyz="0 0 -0.0395"/>
    <parent link="right_arm_elbow_F3_0_link"/>
    <child link="right_arm_elbow_flex_servo_link"/>
  </joint>
  <link name="right_arm_elbow_flex_servo_link">
    <inertial>
      <mass value="0.00001"/>
      <origin xyz="0 0 0"/>
      <inertia ixx="1.0" ixy="0.0" ixz="0.0" iyy="1.0" iyz="0.0" izz="1.0"/>
    </inertial>
    <visual>
      <origin rpy="0 0 0" xyz=" 0 0 0 "/>
      <geometry>
        <mesh filename="package://rbx2_description/meshes/ax12.stl" scale="0.001 0.001 0.001"/>
      </geometry>
      <material name="Black"/>
    </visual>
    <collision>
      <origin rpy="0 0 0" xyz="0.0 0.0 -0.01241"/>
      <geometry>
        <box size="0.025 0.038 0.04762"/>
      </geometry>
    </collision>
  </link>
  <joint name="right_arm_elbow_flex_joint" type="revolute">
    <origin rpy="0 0 0" xyz="0 0 0"/>
    <axis xyz="0 1 0"/>
    <limit effort="1.0" lower="-1.75" upper="1.75" velocity="3.14"/>
    <parent link="right_arm_elbow_flex_servo_link"/>
    <child link="right_arm_elbow_flex_link"/>
  </joint>
  <link name="right_arm_elbow_flex_link">
    <inertial>
      <mass value="0.00001"/>
      <origin xyz="0 0 0"/>
      <inertia ixx="1.0" ixy="0.0" ixz="0.0" iyy="1.0" iyz="0.0" izz="1.0"/>
    </inertial>
    <visual>
      <origin rpy="0 0 0" xyz=" 0 0 0 "/>
      <geometry>
        <mesh filename="package://rbx2_description/meshes/F2.stl" scale="0.001 0.001 0.001"/>
      </geometry>
      <material name="White"/>
    </visual>
    <collision>
      <origin rpy="0 0 0" xyz="0.0 0.0 0.00775"/>
      <geometry>
        <box size="0.025 0.0485 0.0375"/>
      </geometry>
    </collision>
  </link>
  <joint name="right_arm_forearm_F3_0_joint" type="fixed">
    <origin rpy="3.14159 0 1.570795" xyz="0 0 0.02675"/>
    <parent link="right_arm_elbow_flex_link"/>
    <child link="right_arm_forearm_F3_0_link"/>
  </joint>
  <link name="right_arm_forearm_F3_0_link">
    <inertial>
      <mass value="0.00001"/>
      <origin xyz="0 0 0"/>
      <inertia ixx="1.0" ixy="0.0" ixz="0.0" iyy="1.0" iyz="0.0" izz="1.0"/>
    </inertial>
    <visual>
      <origin rpy="0 0 0" xyz=" 0 0 0 "/>
      <geometry>
        <mesh filename="package://rbx2_description/meshes/F3.stl" scale="0.001 0.001 0.001"/>
      </geometry>
      <material name="White"/>
    </visual>
    <collision>
      <origin rpy="0 0 0" xyz="0.0 0.0 -0.0045"/>
      <geometry>
        <box size="0.025 0.038 0.009"/>
      </geometry>
    </collision>
  </link>
  <joint name="right_arm_forearm_flex_servo_joint" type="fixed">
    <origin rpy="3.14159 0 0" xyz="0 0 -0.04375"/>
    <parent link="right_arm_forearm_F3_0_link"/>
    <child link="right_arm_forearm_flex_servo_link"/>
  </joint>
  <link name="right_arm_forearm_flex_servo_link">
    <inertial>
      <mass value="0.00001"/>
      <origin xyz="0 0 0"/>
      <inertia ixx="1.0" ixy="0.0" ixz="0.0" iyy="1.0" iyz="0.0" izz="1.0"/>
    </inertial>
    <visual>
      <origin rpy="0 0 0" xyz=" 0 0 0 "/>
      <geometry>
        <mesh filename="package://rbx2_description/meshes/ax12.stl" scale="0.001 0.001 0.001"/>
      </geometry>
      <material name="Black"/>
    </visual>
    <collision>
      <origin rpy="0 0 0" xyz="0.0 0.0 -0.01241"/>
      <geometry>
        <box size="0.025 0.038 0.04762"/>
      </geometry>
    </collision>
  </link>
  <joint name="right_arm_forearm_flex_joint" type="revolute">
    <origin rpy="0 0 0" xyz="0 0 0"/>
    <axis xyz="0 1 0"/>
    <limit effort="1.0" lower="-1.75" upper="1.75" velocity="3.14"/>
    <parent link="right_arm_forearm_flex_servo_link"/>
    <child link="right_arm_forearm_flex_link"/>
  </joint>
  <link name="right_arm_forearm_flex_link">
    <inertial>
      <mass value="0.00001"/>
      <origin xyz="0 0 0"/>
      <inertia ixx="1.0" ixy="0.0" ixz="0.0" iyy="1.0" iyz="0.0" izz="1.0"/>
    </inertial>
    <visual>
      <origin rpy="0 0 0" xyz=" 0 0 0 "/>
      <geometry>
        <mesh filename="package://rbx2_description/meshes/F2.stl" scale="0.001 0.001 0.001"/>
      </geometry>
      <material name="White"/>
    </visual>
    <collision>
      <origin rpy="0 0 0" xyz="0.0 0.0 0.00775"/>
      <geometry>
        <box size="0.025 0.0485 0.0375"/>
      </geometry>
    </collision>
  </link>
  <joint name="right_arm_forearm_F2_0_joint" type="fixed">
    <origin rpy="0 3.14159 1.570795" xyz="0 0 0.05325"/>
    <parent link="right_arm_forearm_flex_link"/>
    <child link="right_arm_forearm_F2_0_link"/>
  </joint>
  <link name="right_arm_forearm_F2_0_link">
    <inertial>
      <mass value="0.00001"/>
      <origin xyz="0 0 0"/>
      <inertia ixx="1.0" ixy="0.0" ixz="0.0" iyy="1.0" iyz="0.0" izz="1.0"/>
    </inertial>
    <visual>
      <origin rpy="0 0 0" xyz=" 0 0 0 "/>
      <geometry>
        <mesh filename="package://rbx2_description/meshes/F2.stl" scale="0.001 0.001 0.001"/>
      </geometry>
      <material name="White"/>
    </visual>
    <collision>
      <origin rpy="0 0 0" xyz="0.0 0.0 0.00775"/>
      <geometry>
        <box size="0.025 0.0485 0.0375"/>
      </geometry>
    </collision>
  </link>
  <joint name="right_arm_wrist_flex_joint" type="revolute">
    <origin rpy="0 0 0" xyz="0 0 0"/>
    <axis xyz="0 1 0"/>
    <limit effort="1.0" lower="-1.75" upper="1.75" velocity="3.14"/>
    <parent link="right_arm_forearm_F2_0_link"/>
    <child link="right_arm_wrist_flex_link"/>
  </joint>
  <link name="right_arm_wrist_flex_link">
    <inertial>
      <mass value="0.00001"/>
      <origin xyz="0 0 0"/>
      <inertia ixx="1.0" ixy="0.0" ixz="0.0" iyy="1.0" iyz="0.0" izz="1.0"/>
    </inertial>
    <visual>
      <origin rpy="0 0 0" xyz=" 0 0 0 "/>
      <geometry>
        <mesh filename="package://rbx2_description/meshes/ax12.stl" scale="0.001 0.001 0.001"/>
      </geometry>
      <material name="Black"/>
    </visual>
    <collision>
      <origin rpy="0 0 0" xyz="0.0 0.0 -0.01241"/>
      <geometry>
        <box size="0.025 0.038 0.04762"/>
      </geometry>
    </collision>
  </link>
  <joint name="right_arm_wrist_F3_0_joint" type="fixed">
    <origin rpy="3.14159 0 0" xyz="0 0 -0.043"/>
    <parent link="right_arm_wrist_flex_link"/>
    <child link="right_arm_wrist_F3_0_link"/>
  </joint>
  <link name="right_arm_wrist_F3_0_link">
    <inertial>
      <mass value="0.00001"/>
      <origin xyz="0 0 0"/>
      <inertia ixx="1.0" ixy="0.0" ixz="0.0" iyy="1.0" iyz="0.0" izz="1.0"/>
    </inertial>
    <visual>
      <origin rpy="0 0 0" xyz=" 0 0 0 "/>
      <geometry>
        <mesh filename="package://rbx2_description/meshes/F3.stl" scale="0.001 0.001 0.001"/>
      </geometry>
      <material name="White"/>
    </visual>
    <collision>
      <origin rpy="0 0 0" xyz="0.0 0.0 -0.0045"/>
      <geometry>
        <box size="0.025 0.038 0.009"/>
      </geometry>
    </collision>
  </link>
  <joint name="right_arm_gripper_attach_joint" type="fixed">
    <origin rpy="3.14159 0 0" xyz="0 0 0.0005"/>
    <parent link="right_arm_wrist_F3_0_link"/>
    <child link="right_arm_gripper_attach_link"/>
  </joint>
  <link name="right_arm_gripper_attach_link">
    <inertial>
      <mass value="0.00001"/>
      <origin xyz="0 0 0"/>
      <inertia ixx="1.0" ixy="0.0" ixz="0.0" iyy="1.0" iyz="0.0" izz="1.0"/>
    </inertial>
    <visual>
      <origin rpy="0 0 0" xyz=" 0 0 0 "/>
      <geometry>
        <mesh filename="package://rbx2_description/meshes/F3.stl" scale="0.001 0.001 0.001"/>
      </geometry>
      <material name="White"/>
    </visual>
    <collision>
      <origin rpy="0 0 0" xyz="0.0 0.0 -0.0045"/>
      <geometry>
        <box size="0.025 0.038 0.009"/>
      </geometry>
    </collision>
  </link>
  <!-- Attach the right gripper -->
  <joint name="right_gripper_base_joint" type="fixed">
    <origin rpy="0 1.570795 3.14159" xyz="-0.02275 0 -0.0175"/>
    <parent link="right_arm_gripper_attach_link"/>
    <child link="right_gripper_base_link"/>
  </joint>
  <link name="right_gripper_base_link">
    <inertial>
      <mass value="0.00001"/>
      <origin xyz="0 0 0"/>
      <inertia ixx="1.0" ixy="0.0" ixz="0.0" iyy="1.0" iyz="0.0" izz="1.0"/>
    </inertial>
    <visual>
      <origin rpy="0 0 0" xyz=" 0 0 0 "/>
      <geometry>
        <mesh filename="package://rbx2_description/meshes/ax12.stl" scale="0.001 0.001 0.001"/>
      </geometry>
      <material name="Black"/>
    </visual>
    <collision>
      <origin rpy="0 0 0" xyz="0.0 0.0 -0.01241"/>
      <geometry>
        <box size="0.025 0.038 0.04762"/>
      </geometry>
    </collision>
  </link>
  <joint name="right_gripper_finger_joint" type="revolute">
    <origin rpy="0 0 0" xyz="0 0 0"/>
    <axis xyz="0 1 0"/>
    <limit effort="1.0" lower="-0.8" upper="0.5" velocity="3.14"/>
    <parent link="right_gripper_base_link"/>
    <child link="right_gripper_active_finger_bracket_link"/>
  </joint>
  <link name="right_gripper_active_finger_bracket_link">
    <inertial>
      <mass value="0.00001"/>
      <origin xyz="0 0 0"/>
      <inertia ixx="1.0" ixy="0.0" ixz="0.0" iyy="1.0" iyz="0.0" izz="1.0"/>
    </inertial>
    <visual>
      <origin rpy="0 0 0" xyz="0 0 0"/>
      <geometry>
        <mesh filename="package://rbx2_description/meshes/F2.stl" scale="0.001 0.001 0.001"/>
      </geometry>
      <material name="Green"/>
    </visual>
    <collision>
      <origin rpy="0 0 0" xyz="0.0 0.0 0.00775"/>
      <geometry>
        <box size="0.025 0.0485 0.0375"/>
      </geometry>
    </collision>
  </link>
  <joint name="right_gripper_active_finger_joint" type="fixed">
    <origin rpy="0 0 0" xyz="0 0 0.0265"/>
    <parent link="right_gripper_active_finger_bracket_link"/>
    <child link="right_gripper_active_finger_link"/>
  </joint>
  <link name="right_gripper_active_finger_link">
    <inertial>
      <mass value="0.00001"/>
      <origin xyz="0 0 0"/>
      <inertia ixx="1.0" ixy="0.0" ixz="0.0" iyy="1.0" iyz="0.0" izz="1.0"/>
    </inertial>
    <visual>
      <origin rpy="0 0 0" xyz=" 0 0 0 "/>
      <geometry>
        <mesh filename="package://rbx2_description/meshes/finger.stl" scale="0.001 0.001 0.001"/>
      </geometry>
      <material name="Green"/>
    </visual>
    <collision>
      <origin rpy="0 0 0" xyz="0.02645 0.0 -0.00655"/>
      <geometry>
        <box size="0.0783 0.03801 0.0193"/>
      </geometry>
    </collision>
  </link>
  <joint name="right_gripper_static_finger_bracket_joint" type="fixed">
    <origin rpy="0 3.14159 0" xyz="0 0 -0.0425"/>
    <parent link="right_gripper_base_link"/>
    <child link="right_gripper_static_finger_bracket_link"/>
  </joint>
  <link name="right_gripper_static_finger_bracket_link">
    <inertial>
      <mass value="0.00001"/>
      <origin xyz="0 0 0"/>
      <inertia ixx="1.0" ixy="0.0" ixz="0.0" iyy="1.0" iyz="0.0" izz="1.0"/>
    </inertial>
    <visual>
      <origin rpy="0 0 0" xyz=" 0 0 0 "/>
      <geometry>
        <mesh filename="package://rbx2_description/meshes/F3.stl" scale="0.001 0.001 0.001"/>
      </geometry>
      <material name="Green"/>
    </visual>
    <collision>
      <origin rpy="0 0 0" xyz="0.0 0.0 -0.0045"/>
      <geometry>
        <box size="0.025 0.038 0.009"/>
      </geometry>
    </collision>
  </link>
  <joint name="right_gripper_static_finger_joint" type="fixed">
    <origin rpy="0 0 3.14159" xyz="0 0 0"/>
    <parent link="right_gripper_static_finger_bracket_link"/>
    <child link="right_gripper_static_finger_link"/>
  </joint>
  <link name="right_gripper_static_finger_link">
    <inertial>
      <mass value="0.00001"/>
      <origin xyz="0 0 0"/>
      <inertia ixx="1.0" ixy="0.0" ixz="0.0" iyy="1.0" iyz="0.0" izz="1.0"/>
    </inertial>
    <visual>
      <origin rpy="0 0 0" xyz=" 0 0 0 "/>
      <geometry>
        <mesh filename="package://rbx2_description/meshes/finger.stl" scale="0.001 0.001 0.001"/>
      </geometry>
      <material name="Green"/>
    </visual>
    <collision>
      <origin rpy="0 0 0" xyz="0.02645 0.0 -0.00655"/>
      <geometry>
        <box size="0.0783 0.03801 0.0193"/>
      </geometry>
    </collision>
  </link>
  <joint name="right_gripper_joint" type="fixed">
    <origin rpy="-1.570795 0 0" xyz="0.05 0 -0.008"/>
    <parent link="right_gripper_base_link"/>
    <child link="right_gripper_link"/>
  </joint>
  <link name="right_gripper_link">
    <visual>
      <origin rpy="0 0 0" xyz="-0.05 0 0"/>
      <geometry>
        <box size="0.001 0.001 0.001"/>
      </geometry>
    </visual>
    <collision>
      <origin rpy="0 0 0" xyz="-0.05 0 0"/>
      <geometry>
        <box size="0.001 0.001 0.001"/>
      </geometry>
    </collision>
    <!--inertial>
         <mass value="0.0012" />
         <origin xyz="0 0 0"/>
         <inertia ixx="2e-8" ixy="0.0" ixz="0.0"
          iyy="2e-8" iyz="0.0"
          izz="2e-8" />
      </inertial -->
  </link>
</robot>

